Workbook
Name AA_Goodnews: Summary!$Y$17:$Y$21
Name AA_Heritage: Summary!$Y$23:$Y$26
Name AA_Love: Summary!$Y$7:$Y$10
Name AA_Maranatha: Summary!$Y$12:$Y$15
Name AA_Oyigbo: Summary!$Y$28:$Y$36
Name AA_Revival: Summary!$Y$38:$Y$50
Name AA_Zone: Summary!$Y$51,Summary!$Y$37,Summary!$Y$27,Summary!$Y$22,Summary!$Y$16,Summary!$Y$11
Name AD_Goodnews: Summary!$AA$17:$AA$21
Name AD_Heritage: Summary!$AA$23:$AA$26
Name AD_Love: Summary!$AA$7:$AA$10
Name AD_Maranatha: Summary!$AA$12:$AA$15
Name AD_Oyigbo: Summary!$AA$28:$AA$36
Name AD_Revival: Summary!$AA$38:$AA$50
Name AD_Zone: Summary!$AA$11,Summary!$AA$16,Summary!$AA$22,Summary!$AA$27,Summary!$AA$38,Summary!$AA$37,Summary!$AA$51
Name AE_Goodnews: Summary!$AC$17:$AC$21
Name AE_Heritage: Summary!$AC$23:$AC$26
Name AE_Love: Summary!$AC$7:$AC$10
Name AE_Maranatha: Summary!$AC$12:$AC$15
Name AE_Oyigbo: Summary!$AC$28:$AC$36
Name AE_Revival: Summary!$AC$38:$AC$50
Name AE_Zone: Summary!$AC$51,Summary!$AC$37,Summary!$AC$27,Summary!$AC$22,Summary!$AC$16,Summary!$AC$11
Name AF_Goodnews: Summary!$AD$17:$AD$21
Name AF_Heritage: Summary!$AD$23:$AD$26
Name AF_Love: Summary!$AD$7:$AD$10
Name AF_Maranatha: Summary!$AD$12:$AD$15
Name AF_Oyigbo: Summary!$AD$28:$AD$36
Name AF_Revival: Summary!$AD$38:$AD$50
Name AF_Zone: Summary!$AD$51,Summary!$AD$37,Summary!$AD$27,Summary!$AD$22,Summary!$AD$16,Summary!$AD$11
Name AG_Goodnews: Summary!$AE$17:$AE$21
Name AG_Heritage: Summary!$AE$23:$AE$26
Name AG_Love: Summary!$AE$7:$AE$10
Name AG_Maranatha: Summary!$AE$12:$AE$15
Name AG_Oyigbo: Summary!$AE$28:$AE$36
Name AG_Revival: Summary!$AE$38:$AE$50
Name AG_Zone: Summary!$AE$51,Summary!$AE$37,Summary!$AE$27,Summary!$AE$22,Summary!$AE$16,Summary!$AE$11
Name AL_Goodnews: Summary!$AJ$17:$AJ$21
Name AL_Heritage: Summary!$AJ$23:$AJ$26
Name AL_Love: Summary!$AJ$7:$AJ$10
Name AL_Maranatha: Summary!$AJ$12:$AJ$15
Name AL_Oyigbo: Summary!$AJ$28:$AJ$36
Name AL_Revival: Summary!$AJ$38:$AJ$50
Name AL_Zone: Summary!$AJ$11,Summary!$AJ$16,Summary!$AJ$22,Summary!$AJ$27,Summary!$AJ$37,Summary!$AJ$51
Name AM_Goodnews: Summary!$AK$17:$AK$21
Name AM_Heritage: Summary!$AK$23:$AK$26
Name AM_Love: Summary!$AK$7:$AK$10
Name AM_Maranatha: Summary!$AK$12:$AK$15
Name AM_Oyigbo: Summary!$AK$28:$AK$36
Name AM_Revival: Summary!$AK$38:$AK$50
Name AM_Zone: Summary!$AK$51,Summary!$AK$37,Summary!$AK$27,Summary!$AK$22,Summary!$AK$16,Summary!$AK$11
Name AN_Goodnews: Summary!$AL$17:$AL$21
Name AN_Heritage: Summary!$AL$23:$AL$26
Name AN_Love: Summary!$AL$7:$AL$10
Name AN_Maranatha: Summary!$AL$12:$AL$15
Name AN_Oyigbo: Summary!$AL$28:$AL$36
Name AN_Revival: Summary!$AL$38:$AL$50
Name AN_Zone: Summary!$AL$11,Summary!$AL$16,Summary!$AL$22,Summary!$AL$27,Summary!$AL$37,Summary!$AL$51
Name AO_Goodnews: Summary!$AM$17:$AM$21
Name AO_Heritage: Summary!$AM$23:$AM$26
Name AO_Love: Summary!$AM$7:$AM$10
Name AO_Maranatha: Summary!$AM$12:$AM$15

Sheet Summary
A4: JANUARY, 2024 | F4: Monthly Totals | S4: Monthly Ranking
A5: Zones | B5: Location | C5: Pst Phone Number | D5: Pastor Name | E5: Church Name | F5: Attendance | N5: Income | P5: Allocations | R5: Attendance to Programmes
F6: Male | G6: Female | H6: Children | I6: Total | J6: Visitors' Volume | K6: Visitors' Retention Rate | L6: Members' Backdoor Rate | M6: Target Compliance Rate | N6: Total | O6: Income per Member | P6: Total | Q6: COT [Cut Off Date] | S6: Visitors' Volume | T6: Visitors' Retention Rate | U6: Members' Backdoor Rate | V6: Target Compliance Rate | W6: Income per Member (₦) | X6: Total Allocations | Y6: Cut Off Date (COD) | Z6: Attendance to Programmes | AA6: Aggregate | AB6: Position
A7: Love [Pst. Paulinus Nsirim] | B7: Rumuomasi | C7: 8162286241 | D7: Pst. Daniel Chukwuma | E7: Rehoboth | F7: =ROUNDDOWN(SUM('WK1:WK5'!B6)/MAX(1,INDEX(FREQUENCY('WK1:WK5'!B6,0),2)),0) -> 86 | G7: =ROUNDDOWN(SUM('WK1:WK5'!C6)/MAX(1,INDEX(FREQUENCY('WK1:WK5'!C6,0),2)),0) -> 89 | H7: =ROUNDDOWN(SUM('WK1:WK5'!D6)/MAX(1,INDEX(FREQUENCY('WK1:WK5'!D6,0),2)),0) -> 76 | I7: =SUM(F7:H7) -> 251 | J7: =SUM('WK1:WK5'!O6) -> 6 | K7: =IF(AND((SUM([1]Summary!J7,J7)>0),[1]Summary!I7>0),(I7-(([1]Summary!I7-[1]Summary!J7)-(L7*([1]Summary!I7-[1]Summary!J7))))/(IF(SUM([1]Summary!J7,J7)>0,[1]Summary!J7+J7,0)),0%) -> 0.75 | L7: =IF(([1]Summary!I7)>0,(([1]Summary!I7-[1]Summary!J7)-(I7-J7))/(([1]Summary!I7-[1]Summary!J7)),100%) -> -0.16666667 | M7: =IF(I7=0,0%,IF((I7-[2]Sheet1!$G3+([2]Sheet1!$J3/12*1))=0, 0%,(I7-[2]Sheet1!$G3+([2]Sheet1!$J3/12*1))/([2]Sheet1!$G3+([2]Sheet1!$J3/12*1)))) -> -0.19000761 | N7: =SUM('WK1:WK5'!M6) -> 324340 | O7: =(SUM('WK1:WK5'!M6)/MAX(1,INDEX(FREQUENCY('WK1:WK5'!M6,0),2)))/IF(F7+G7>0,F7+G7,"1") -> 463.34286 | P7: =SUM(IF(SUM('WK1:WK5'!J6)>0,SUM('WK1:WK5'!T6)/((SUM('WK1:WK5'!J6)+SUM('WK1:WK5'!K6)+SUM('WK1:WK5'!P6))*0.3),0%),IF(SUM('WK1:WK5'!J6)>0,SUM('WK1:WK5'!U6)/((SUM('WK1:WK5'!J6)+SUM('WK1:WK5'!K6)+SUM('WK1:WK5'!P6))*0.1),0%),IF(SUM('WK1:WK5'!J6)>0,SUM('WK1:WK5'!V6)/((SUM('WK1:WK5'!J6)+SUM('WK1:WK5'!K6)+SUM('WK1:WK5'!P6))*0.3),0%)) -> 0 | Q7: =SUM('WK1:WK5'!Z6)/MAX(1,INDEX(FREQUENCY('WK1:WK5'!Z6,0),2)) -> 0 | R7: =IF(I7>0,SUM('WK1:WK5'!AE6)/MAX(1,INDEX(FREQUENCY('WK1:WK5'!AE6,0),2))/I7,0) -> 0 | S7: =RANK($J7,(J_Love,J_Maranatha,J_Goodnews,J_Heritage,J_Oyigbo,J_Revival)) -> 6 | T7: =RANK($K7,(K_Love,K_Maranatha,K_Goodnews,K_Heritage,K_Oyigbo,K_Revival)) -> 5 | U7: =RANK($L7,(L_Love,L_Maranatha,L_Goodnews,L_Heritage,L_Oyigbo,L_Revival),1) -> 13 | V7: =RANK($M7,(M_Love,M_Maranatha,M_Goodnews,M_Heritage,M_Oyigbo,M_Revival)) -> 31 | W7: =RANK($O7,(O_Love,O_Maranatha,O_Goodnews,O_Heritage,O_Oyigbo,O_Revival)) -> 10 | X7: =RANK($P7,(P_Love,P_Maranatha,P_Goodnews,P_Heritage,P_Oyigbo,P_Revival)) -> 1 | Y7: =RANK($Q7,(Q_Love,Q_Maranatha,Q_Goodnews,Q_Heritage,Q_Oyigbo,Q_Revival)) -> 1 | Z7: =RANK($R7,(R_Love,R_Maranatha,R_Goodnews,R_Heritage,R_Oyigbo,R_Revival)) -> 1 | AA7: =SUM(S7:Z7) -> 68 | AB7: =RANK(AA7,(AD_Love,AD_Maranatha,AD_Goodnews,AD_Heritage,AD_Oyigbo,AD_Revival),1) -> 11
B8: Woji | C8: 8037060592 | D8: Pst. Ikechukwu Uzoma | E8: Love International | F8: =ROUNDDOWN(SUM('WK1:WK5'!B7)/MAX(1,INDEX(FREQUENCY('WK1:WK5'!B7,0),2)),0) -> 82 | G8: =ROUNDDOWN(SUM('WK1:WK5'!C7)/MAX(1,INDEX(FREQUENCY('WK1:WK5'!C7,0),2)),0) -> 105 | H8: =ROUNDDOWN(SUM('WK1:WK5'!D7)/MAX(1,INDEX(FREQUENCY('WK1:WK5'!D7,0),2)),0) -> 81 | I8: =SUM(F8:H8) -> 268 | J8: =SUM('WK1:WK5'!O7) -> 9 | K8: =IF(AND((SUM([1]Summary!J8,J8)>0),[1]Summary!I8>0),(I8-(([1]Summary!I8-[1]Summary!J8)-(L8*([1]Summary!I8-[1]Summary!J8))))/(IF(SUM([1]Summary!J8,J8)>0,[1]Summary!J8+J8,0)),0%) -> 0.36 | L8: =IF(([1]Summary!I8)>0,(([1]Summary!I8-[1]Summary!J8)-(I8-J8))/(([1]Summary!I8-[1]Summary!J8)),100%) -> -0.35602094 | M8: =IF(I8=0,0%,IF((I8-[2]Sheet1!$G4+([2]Sheet1!$J4/12*1))=0, 0%,(I8-[2]Sheet1!$G4+([2]Sheet1!$J4/12*1))/([2]Sheet1!$G4+([2]Sheet1!$J4/12*1)))) -> 0.023037228 | N8: =SUM('WK1:WK5'!M7) -> 266420 | O8: =(SUM('WK1:WK5'!M7)/MAX(1,INDEX(FREQUENCY('WK1:WK5'!M7,0),2)))/IF(F8+G8>0,F8+G8,"1") -> 356.17647 | P8: =SUM(IF(SUM('WK1:WK5'!J7)>0,SUM('WK1:WK5'!T7)/((SUM('WK1:WK5'!J7)+SUM('WK1:WK5'!K7)+SUM('WK1:WK5'!P7))*0.3),0%),IF(SUM('WK1:WK5'!J7)>0,SUM('WK1:WK5'!U7)/((SUM('WK1:WK5'!J7)+SUM('WK1:WK5'!K7)+SUM('WK1:WK5'!P7))*0.1),0%),IF(SUM('WK1:WK5'!J7)>0,SUM('WK1:WK5'!V7)/((SUM('WK1:WK5'!J7)+SUM('WK1:WK5'!K7)+SUM('WK1:WK5'!P7))*0.3),0%)) -> 0 | Q8: =SUM('WK1:WK5'!Z7)/MAX(1,INDEX(FREQUENCY('WK1:WK5'!Z7,0),2)) -> 0 | R8: =IF(I8>0,SUM('WK1:WK5'!AE7)/MAX(1,INDEX(FREQUENCY('WK1:WK5'!AE7,0),2))/I8,0) -> 0 | S8: =RANK($J8,(J_Love,J_Maranatha,J_Goodnews,J_Heritage,J_Oyigbo,J_Revival)) -> 5 | T8: =RANK($K8,(K_Love,K_Maranatha,K_Goodnews,K_Heritage,K_Oyigbo,K_Revival)) -> 9 | U8: =RANK($L8,(L_Love,L_Maranatha,L_Goodnews,L_Heritage,L_Oyigbo,L_Revival),1) -> 5 | V8: =RANK($M8,(M_Love,M_Maranatha,M_Goodnews,M_Heritage,M_Oyigbo,M_Revival)) -> 9 | W8: =RANK($O8,(O_Love,O_Maranatha,O_Goodnews,O_Heritage,O_Oyigbo,O_Revival)) -> 13 | X8: =RANK($P8,(P_Love,P_Maranatha,P_Goodnews,P_Heritage,P_Oyigbo,P_Revival)) -> 1 | Y8: =RANK($Q8,(Q_Love,Q_Maranatha,Q_Goodnews,Q_Heritage,Q_Oyigbo,Q_Revival)) -> 1 | Z8: =RANK($R8,(R_Love,R_Maranatha,R_Goodnews,R_Heritage,R_Oyigbo,R_Revival)) -> 1 | AA8: =SUM(S8:Z8) -> 44 | AB8: =RANK(AA8,(AD_Love,AD_Maranatha,AD_Goodnews,AD_Heritage,AD_Oyigbo,AD_Revival),1) -> 1
B9: Oginigba | C9: 8033381017 | D9: Pst. Vincent Ameh | E9: Throne of Greatness | F9: =ROUNDDOWN(SUM('WK1:WK5'!B8)/MAX(1,INDEX(FREQUENCY('WK1:WK5'!B8,0),2)),0) -> 3 | G9: =ROUNDDOWN(SUM('WK1:WK5'!C8)/MAX(1,INDEX(FREQUENCY('WK1:WK5'!C8,0),2)),0) -> 7 | H9: =ROUNDDOWN(SUM('WK1:WK5'!D8)/MAX(1,INDEX(FREQUENCY('WK1:WK5'!D8,0),2)),0) -> 1 | I9: =SUM(F9:H9) -> 11 | J9: =SUM('WK1:WK5'!O8) -> 0 | K9: =IF(AND((SUM([1]Summary!J9,J9)>0),[1]Summary!I9>0),(I9-(([1]Summary!I9-[1]Summary!J9)-(L9*([1]Summary!I9-[1]Summary!J9))))/(IF(SUM([1]Summary!J9,J9)>0,[1]Summary!J9+J9,0)),0%) -> 0 | L9: =IF(([1]Summary!I9)>0,(([1]Summary!I9-[1]Summary!J9)-(I9-J9))/(([1]Summary!I9-[1]Summary!J9)),100%) -> 0.15384615 | M9: =IF(I9=0,0%,IF((I9-[2]Sheet1!$G5+([2]Sheet1!$J5/12*1))=0, 0%,(I9-[2]Sheet1!$G5+([2]Sheet1!$J5/12*1))/([2]Sheet1!$G5+([2]Sheet1!$J5/12*1)))) -> -0.12111618 | N9: =SUM('WK1:WK5'!M8) -> 13400 | O9: =(SUM('WK1:WK5'!M8)/MAX(1,INDEX(FREQUENCY('WK1:WK5'!M8,0),2)))/IF(F9+G9>0,F9+G9,"1") -> 335 | P9: =SUM(IF(SUM('WK1:WK5'!J8)>0,SUM('WK1:WK5'!T8)/((SUM('WK1:WK5'!J8)+SUM('WK1:WK5'!K8)+SUM('WK1:WK5'!P8))*0.3),0%),IF(SUM('WK1:WK5'!J8)>0,SUM('WK1:WK5'!U8)/((SUM('WK1:WK5'!J8)+SUM('WK1:WK5'!K8)+SUM('WK1:WK5'!P8))*0.1),0%),IF(SUM('WK1:WK5'!J8)>0,SUM('WK1:WK5'!V8)/((SUM('WK1:WK5'!J8)+SUM('WK1:WK5'!K8)+SUM('WK1:WK5'!P8))*0.3),0%)) -> 0 | Q9: =SUM('WK1:WK5'!Z8)/MAX(1,INDEX(FREQUENCY('WK1:WK5'!Z8,0),2)) -> 0 | R9: =IF(I9>0,SUM('WK1:WK5'!AE8)/MAX(1,INDEX(FREQUENCY('WK1:WK5'!AE8,0),2))/I9,0) -> 0 | S9: =RANK($J9,(J_Love,J_Maranatha,J_Goodnews,J_Heritage,J_Oyigbo,J_Revival)) -> 17 | T9: =RANK($K9,(K_Love,K_Maranatha,K_Goodnews,K_Heritage,K_Oyigbo,K_Revival)) -> 17 | U9: =RANK($L9,(L_Love,L_Maranatha,L_Goodnews,L_Heritage,L_Oyigbo,L_Revival),1) -> 26 | V9: =RANK($M9,(M_Love,M_Maranatha,M_Goodnews,M_Heritage,M_Oyigbo,M_Revival)) -> 27 | W9: =RANK($O9,(O_Love,O_Maranatha,O_Goodnews,O_Heritage,O_Oyigbo,O_Revival)) -> 16 | X9: =RANK($P9,(P_Love,P_Maranatha,P_Goodnews,P_Heritage,P_Oyigbo,P_Revival)) -> 1 | Y9: =RANK($Q9,(Q_Love,Q_Maranatha,Q_Goodnews,Q_Heritage,Q_Oyigbo,Q_Revival)) -> 1 | Z9: =RANK($R9,(R_Love,R_Maranatha,R_Goodnews,R_Heritage,R_Oyigbo,R_Revival)) -> 1 | AA9: =SUM(S9:Z9) -> 106 | AB9: =RANK(AA9,(AD_Love,AD_Maranatha,AD_Goodnews,AD_Heritage,AD_Oyigbo,AD_Revival),1) -> 25
B10: Rumuigbo | C10: 8064733165 | D10: Pst. Anslem Sunkle | E10: Shekinar Glory | F10: =ROUNDDOWN(SUM('WK1:WK5'!B9)/MAX(1,INDEX(FREQUENCY('WK1:WK5'!B9,0),2)),0) -> 11 | G10: =ROUNDDOWN(SUM('WK1:WK5'!C9)/MAX(1,INDEX(FREQUENCY('WK1:WK5'!C9,0),2)),0) -> 10 | H10: =ROUNDDOWN(SUM('WK1:WK5'!D9)/MAX(1,INDEX(FREQUENCY('WK1:WK5'!D9,0),2)),0) -> 6 | I10: =SUM(F10:H10) -> 27 | J10: =SUM('WK1:WK5'!O9) -> 0 | K10: =IF(AND((SUM([1]Summary!J10,J10)>0),[1]Summary!I10>0),(I10-(([1]Summary!I10-[1]Summary!J10)-(L10*([1]Summary!I10-[1]Summary!J10))))/(IF(SUM([1]Summary!J10,J10)>0,[1]Summary!J10+J10,0)),0%) -> 0 | L10: =IF(([1]Summary!I10)>0,(([1]Summary!I10-[1]Summary!J10)-(I10-J10))/(([1]Summary!I10-[1]Summary!J10)),100%) -> -1.0769231 | M10: =IF(I10=0,0%,IF((I10-[2]Sheet1!$G6+([2]Sheet1!$J6/12*1))=0, 0%,(I10-[2]Sheet1!$G6+([2]Sheet1!$J6/12*1))/([2]Sheet1!$G6+([2]Sheet1!$J6/12*1)))) -> 0.089134566 | N10: =SUM('WK1:WK5'!M9) -> 25400 | O10: =(SUM('WK1:WK5'!M9)/MAX(1,INDEX(FREQUENCY('WK1:WK5'!M9,0),2)))/IF(F10+G10>0,F10+G10,"1") -> 302.38095 | P10: =SUM(IF(SUM('WK1:WK5'!J9)>0,SUM('WK1:WK5'!T9)/((SUM('WK1:WK5'!J9)+SUM('WK1:WK5'!K9)+SUM('WK1:WK5'!P9))*0.3),0%),IF(SUM('WK1:WK5'!J9)>0,SUM('WK1:WK5'!U9)/((SUM('WK1:WK5'!J9)+SUM('WK1:WK5'!K9)+SUM('WK1:WK5'!P9))*0.1),0%),IF(SUM('WK1:WK5'!J9)>0,SUM('WK1:WK5'!V9)/((SUM('WK1:WK5'!J9)+SUM('WK1:WK5'!K9)+SUM('WK1:WK5'!P9))*0.3),0%)) -> 0 | Q10: =SUM('WK1:WK5'!Z9)/MAX(1,INDEX(FREQUENCY('WK1:WK5'!Z9,0),2)) -> 0 | R10: =IF(I10>0,SUM('WK1:WK5'!AE9)/MAX(1,INDEX(FREQUENCY('WK1:WK5'!AE9,0),2))/I10,0) -> 0 | S10: =RANK($J10,(J_Love,J_Maranatha,J_Goodnews,J_Heritage,J_Oyigbo,J_Revival)) -> 17 | T10: =RANK($K10,(K_Love,K_Maranatha,K_Goodnews,K_Heritage,K_Oyigbo,K_Revival)) -> 17 | U10: =RANK($L10,(L_Love,L_Maranatha,L_Goodnews,L_Heritage,L_Oyigbo,L_Revival),1) -> 1 | V10: =RANK($M10,(M_Love,M_Maranatha,M_Goodnews,M_Heritage,M_Oyigbo,M_Revival)) -> 6 | W10: =RANK($O10,(O_Love,O_Maranatha,O_Goodnews,O_Heritage,O_Oyigbo,O_Revival)) -> 18 | X10: =RANK($P10,(P_Love,P_Maranatha,P_Goodnews,P_Heritage,P_Oyigbo,P_Revival)) -> 1 | Y10: =RANK($Q10,(Q_Love,Q_Maranatha,Q_Goodnews,Q_Heritage,Q_Oyigbo,Q_Revival)) -> 1 | Z10: =RANK($R10,(R_Love,R_Maranatha,R_Goodnews,R_Heritage,R_Oyigbo,R_Revival)) -> 1 | AA10: =SUM(S10:Z10) -> 62 | AB10: =RANK(AA10,(AD_Love,AD_Maranatha,AD_Goodnews,AD_Heritage,AD_Oyigbo,AD_Revival),1) -> 8
B11: TOTAL | F11: =SUM(F7:F10) -> 182 | G11: =SUM(G7:G10) -> 211 | H11: =SUM(H7:H10) -> 164 | I11: =SUM(I7:I10) -> 557 | J11: =SUM(J7:J10) -> 15 | K11: =IF(SUM(K7:K10)>0,AVERAGEIF(K7:K10,"<>0"),0) -> 0.555 | L11: =IF(SUM(L7:L10)=0,100%,AVERAGEIF(L7:L10,"<>0")) -> -0.36144113 | M11: =IF(SUM(M7:M10)=0,0%,AVERAGEIF(M7:M10,"<>0")) -> -0.049737999 | N11: =SUM(N7:N10) -> 629560 | O11: =IF(SUM(O7:O10)>0,AVERAGEIF(O7:O10,"<>0"),0) -> 364.22507 | P11: =IF(SUM(P7:P10)>0,AVERAGEIF(P7:P10,"<>0"),0%) -> 0 | Q11: =IF(SUM(Q7:Q10)>0,AVERAGEIF(Q7:Q10,"<>0"),0) -> 0 | R11: =IF(SUM(R7:R10)>0,AVERAGEIF(R7:R10,"<>0"),0) -> 0 | S11: =RANK($J11,J_Zone) -> 3 | T11: =RANK($K11,K_Zone) -> 3 | U11: =RANK($L11,L_Zone) -> 6 | V11: =RANK($M11,M_Zone) -> 3 | W11: =RANK($O11,O_Zone) -> 4 | X11: =RANK($P11,P_Zone) -> 1 | Y11: =RANK($Q11,Q_Zone) -> 1 | Z11: =RANK($R11,R_Zone) -> 1 | AA11: =SUM(S11:Z11) -> 22 | AB11: =RANK(AA11,AD_Zone,1) -> 5
A12: Maranatha [Pst. David Michael] | B12: D - Line | C12: 7031215541 | D12: Pst. Uchenna John | E12: Zion Faith Int'l | F12: =ROUNDDOWN(SUM('WK1:WK5'!B11)/MAX(1,INDEX(FREQUENCY('WK1:WK5'!B11,0),2)),0) -> 79 | G12: =ROUNDDOWN(SUM('WK1:WK5'!C11)/MAX(1,INDEX(FREQUENCY('WK1:WK5'!C11,0),2)),0) -> 81 | H12: =ROUNDDOWN(SUM('WK1:WK5'!D11)/MAX(1,INDEX(FREQUENCY('WK1:WK5'!D11,0),2)),0) -> 72 | I12: =SUM(F12:H12) -> 232 | J12: =SUM('WK1:WK5'!O11) -> 1 | K12: =IF(AND((SUM([1]Summary!J12,J12)>0),[1]Summary!I12>0),(I12-(([1]Summary!I12-[1]Summary!J12)-(L12*([1]Summary!I12-[1]Summary!J12))))/(IF(SUM([1]Summary!J12,J12)>0,[1]Summary!J12+J12,0)),0%) -> 0.33333333 | L12: =IF(([1]Summary!I12)>0,(([1]Summary!I12-[1]Summary!J12)-(I12-J12))/(([1]Summary!I12-[1]Summary!J12)),100%) -> -0.13793103 | M12: =IF(I12=0,0%,IF((I12-[2]Sheet1!$G8+([2]Sheet1!$J8/12*1))=0, 0%,(I12-[2]Sheet1!$G8+([2]Sheet1!$J8/12*1))/([2]Sheet1!$G8+([2]Sheet1!$J8/12*1)))) -> -0.23438471 | N12: =SUM('WK1:WK5'!M11) -> 176610 | O12: =(SUM('WK1:WK5'!M11)/MAX(1,INDEX(FREQUENCY('WK1:WK5'!M11,0),2)))/IF(F12+G12>0,F12+G12,"1") -> 275.95312 | P12: =SUM(IF(SUM('WK1:WK5'!J11)>0,SUM('WK1:WK5'!T11)/((SUM('WK1:WK5'!J11)+SUM('WK1:WK5'!K11)+SUM('WK1:WK5'!P11))*0.3),0%),IF(SUM('WK1:WK5'!J11)>0,SUM('WK1:WK5'!U11)/((SUM('WK1:WK5'!J11)+SUM('WK1:WK5'!K11)+SUM('WK1:WK5'!P11))*0.1),0%),IF(SUM('WK1:WK5'!J11)>0,SUM('WK1:WK5'!V11)/((SUM('WK1:WK5'!J11)+SUM('WK1:WK5'!K11)+SUM('WK1:WK5'!P11))*0.3),0%)) -> 0 | Q12: =SUM('WK1:WK5'!Z11)/MAX(1,INDEX(FREQUENCY('WK1:WK5'!Z11,0),2)) -> 0 | R12: =IF(I12>0,SUM('WK1:WK5'!AE11)/MAX(1,INDEX(FREQUENCY('WK1:WK5'!AE11,0),2))/I12,0) -> 0 | S12: =RANK($J12,(J_Love,J_Maranatha,J_Goodnews,J_Heritage,J_Oyigbo,J_Revival)) -> 13 | T12: =RANK($K12,(K_Love,K_Maranatha,K_Goodnews,K_Heritage,K_Oyigbo,K_Revival)) -> 10 | U12: =RANK($L12,(L_Love,L_Maranatha,L_Goodnews,L_Heritage,L_Oyigbo,L_Revival),1) -> 15 | V12: =RANK($M12,(M_Love,M_Maranatha,M_Goodnews,M_Heritage,M_Oyigbo,M_Revival)) -> 35 | W12: =RANK($O12,(O_Love,O_Maranatha,O_Goodnews,O_Heritage,O_Oyigbo,O_Revival)) -> 22 | X12: =RANK($P12,(P_Love,P_Maranatha,P_Goodnews,P_Heritage,P_Oyigbo,P_Revival)) -> 1 | Y12: =RANK($Q12,(Q_Love,Q_Maranatha,Q_Goodnews,Q_Heritage,Q_Oyigbo,Q_Revival)) -> 1 | Z12: =RANK($R12,(R_Love,R_Maranatha,R_Goodnews,R_Heritage,R_Oyigbo,R_Revival)) -> 1 | AA12: =SUM(S12:Z12) -> 98 | AB12: =RANK(AA12,(AD_Love,AD_Maranatha,AD_Goodnews,AD_Heritage,AD_Oyigbo,AD_Revival),1) -> 23
B13: Borokiri | C13: 8033381856 | D13: Pst. David Michael | E13: Maranatha | F13: =ROUNDDOWN(SUM('WK1:WK5'!B12)/MAX(1,INDEX(FREQUENCY('WK1:WK5'!B12,0),2)),0) -> 24 | G13: =ROUNDDOWN(SUM('WK1:WK5'!C12)/MAX(1,INDEX(FREQUENCY('WK1:WK5'!C12,0),2)),0) -> 42 | H13: =ROUNDDOWN(SUM('WK1:WK5'!D12)/MAX(1,INDEX(FREQUENCY('WK1:WK5'!D12,0),2)),0) -> 45 | I13: =SUM(F13:H13) -> 111 | J13: =SUM('WK1:WK5'!O12) -> 1 | K13: =IF(AND((SUM([1]Summary!J13,J13)>0),[1]Summary!I13>0),(I13-(([1]Summary!I13-[1]Summary!J13)-(L13*([1]Summary!I13-[1]Summary!J13))))/(IF(SUM([1]Summary!J13,J13)>0,[1]Summary!J13+J13,0)),0%) -> 0.071428571 | L13: =IF(([1]Summary!I13)>0,(([1]Summary!I13-[1]Summary!J13)-(I13-J13))/(([1]Summary!I13-[1]Summary!J13)),100%) -> -0.27906977 | M13: =IF(I13=0,0%,IF((I13-[2]Sheet1!$G9+([2]Sheet1!$J9/12*1))=0, 0%,(I13-[2]Sheet1!$G9+([2]Sheet1!$J9/12*1))/([2]Sheet1!$G9+([2]Sheet1!$J9/12*1)))) -> 0.30703803 | N13: =SUM('WK1:WK5'!M12) -> 86340 | O13: =(SUM('WK1:WK5'!M12)/MAX(1,INDEX(FREQUENCY('WK1:WK5'!M12,0),2)))/IF(F13+G13>0,F13+G13,"1") -> 327.04545 | P13: =SUM(IF(SUM('WK1:WK5'!J12)>0,SUM('WK1:WK5'!T12)/((SUM('WK1:WK5'!J12)+SUM('WK1:WK5'!K12)+SUM('WK1:WK5'!P12))*0.3),0%),IF(SUM('WK1:WK5'!J12)>0,SUM('WK1:WK5'!U12)/((SUM('WK1:WK5'!J12)+SUM('WK1:WK5'!K12)+SUM('WK1:WK5'!P12))*0.1),0%),IF(SUM('WK1:WK5'!J12)>0,SUM('WK1:WK5'!V12)/((SUM('WK1:WK5'!J12)+SUM('WK1:WK5'!K12)+SUM('WK1:WK5'!P12))*0.3),0%)) -> 0 | Q13: =SUM('WK1:WK5'!Z12)/MAX(1,INDEX(FREQUENCY('WK1:WK5'!Z12,0),2)) -> 0 | R13: =IF(I13>0,SUM('WK1:WK5'!AE12)/MAX(1,INDEX(FREQUENCY('WK1:WK5'!AE12,0),2))/I13,0) -> 0 | S13: =RANK($J13,(J_Love,J_Maranatha,J_Goodnews,J_Heritage,J_Oyigbo,J_Revival)) -> 13 | T13: =RANK($K13,(K_Love,K_Maranatha,K_Goodnews,K_Heritage,K_Oyigbo,K_Revival)) -> 15 | U13: =RANK($L13,(L_Love,L_Maranatha,L_Goodnews,L_Heritage,L_Oyigbo,L_Revival),1) -> 6 | V13: =RANK($M13,(M_Love,M_Maranatha,M_Goodnews,M_Heritage,M_Oyigbo,M_Revival)) -> 3 | W13: =RANK($O13,(O_Love,O_Maranatha,O_Goodnews,O_Heritage,O_Oyigbo,O_Revival)) -> 17 | X13: =RANK($P13,(P_Love,P_Maranatha,P_Goodnews,P_Heritage,P_Oyigbo,P_Revival)) -> 1 | Y13: =RANK($Q13,(Q_Love,Q_Maranatha,Q_Goodnews,Q_Heritage,Q_Oyigbo,Q_Revival)) -> 1 | Z13: =RANK($R13,(R_Love,R_Maranatha,R_Goodnews,R_Heritage,R_Oyigbo,R_Revival)) -> 1 | AA13: =SUM(S13:Z13) -> 57 | AB13: =RANK(AA13,(AD_Love,AD_Maranatha,AD_Goodnews,AD_Heritage,AD_Oyigbo,AD_Revival),1) -> 6
B14: Odili Road | C14: 8033134839 | D14: Pst. Martins Agbo | E14: Elevation | F14: =ROUNDDOWN(SUM('WK1:WK5'!B13)/MAX(1,INDEX(FREQUENCY('WK1:WK5'!B13,0),2)),0) -> 21 | G14: =ROUNDDOWN(SUM('WK1:WK5'!C13)/MAX(1,INDEX(FREQUENCY('WK1:WK5'!C13,0),2)),0) -> 24 | H14: =ROUNDDOWN(SUM('WK1:WK5'!D13)/MAX(1,INDEX(FREQUENCY('WK1:WK5'!D13,0),2)),0) -> 30 | I14: =SUM(F14:H14) -> 75 | J14: =SUM('WK1:WK5'!O13) -> 0 | K14: =IF(AND((SUM([1]Summary!J14,J14)>0),[1]Summary!I14>0),(I14-(([1]Summary!I14-[1]Summary!J14)-(L14*([1]Summary!I14-[1]Summary!J14))))/(IF(SUM([1]Summary!J14,J14)>0,[1]Summary!J14+J14,0)),0%) -> 0 | L14: =IF(([1]Summary!I14)>0,(([1]Summary!I14-[1]Summary!J14)-(I14-J14))/(([1]Summary!I14-[1]Summary!J14)),100%) -> 0.074074074 | M14: =IF(I14=0,0%,IF((I14-[2]Sheet1!$G10+([2]Sheet1!$J10/12*1))=0, 0%,(I14-[2]Sheet1!$G10+([2]Sheet1!$J10/12*1))/([2]Sheet1!$G10+([2]Sheet1!$J10/12*1)))) -> 0.30938839 | N14: =SUM('WK1:WK5'!M13) -> 131930 | O14: =(SUM('WK1:WK5'!M13)/MAX(1,INDEX(FREQUENCY('WK1:WK5'!M13,0),2)))/IF(F14+G14>0,F14+G14,"1") -> 732.94444 | P14: =SUM(IF(SUM('WK1:WK5'!J13)>0,SUM('WK1:WK5'!T13)/((SUM('WK1:WK5'!J13)+SUM('WK1:WK5'!K13)+SUM('WK1:WK5'!P13))*0.3),0%),IF(SUM('WK1:WK5'!J13)>0,SUM('WK1:WK5'!U13)/((SUM('WK1:WK5'!J13)+SUM('WK1:WK5'!K13)+SUM('WK1:WK5'!P13))*0.1),0%),IF(SUM('WK1:WK5'!J13)>0,SUM('WK1:WK5'!V13)/((SUM('WK1:WK5'!J13)+SUM('WK1:WK5'!K13)+SUM('WK1:WK5'!P13))*0.3),0%)) -> 0 | Q14: =SUM('WK1:WK5'!Z13)/MAX(1,INDEX(FREQUENCY('WK1:WK5'!Z13,0),2)) -> 0 | R14: =IF(I14>0,SUM('WK1:WK5'!AE13)/MAX(1,INDEX(FREQUENCY('WK1:WK5'!AE13,0),2))/I14,0) -> 0 | S14: =RANK($J14,(J_Love,J_Maranatha,J_Goodnews,J_Heritage,J_Oyigbo,J_Revival)) -> 17 | T14: =RANK($K14,(K_Love,K_Maranatha,K_Goodnews,K_Heritage,K_Oyigbo,K_Revival)) -> 17 | U14: =RANK($L14,(L_Love,L_Maranatha,L_Goodnews,L_Heritage,L_Oyigbo,L_Revival),1) -> 22 | V14: =RANK($M14,(M_Love,M_Maranatha,M_Goodnews,M_Heritage,M_Oyigbo,M_Revival)) -> 2 | W14: =RANK($O14,(O_Love,O_Maranatha,O_Goodnews,O_Heritage,O_Oyigbo,O_Revival)) -> 2 | X14: =RANK($P14,(P_Love,P_Maranatha,P_Goodnews,P_Heritage,P_Oyigbo,P_Revival)) -> 1 | Y14: =RANK($Q14,(Q_Love,Q_Maranatha,Q_Goodnews,Q_Heritage,Q_Oyigbo,Q_Revival)) -> 1 | Z14: =RANK($R14,(R_Love,R_Maranatha,R_Goodnews,R_Heritage,R_Oyigbo,R_Revival)) -> 1 | AA14: =SUM(S14:Z14) -> 63 | AB14: =RANK(AA14,(AD_Love,AD_Maranatha,AD_Goodnews,AD_Heritage,AD_Oyigbo,AD_Revival),1) -> 9
B15: Bonny Island | C15: 8131632175 | D15: Pst. Jeremiah Godswill | E15: Precious | F15: =ROUNDDOWN(SUM('WK1:WK5'!B14)/MAX(1,INDEX(FREQUENCY('WK1:WK5'!B14,0),2)),0) -> 3 | G15: =ROUNDDOWN(SUM('WK1:WK5'!C14)/MAX(1,INDEX(FREQUENCY('WK1:WK5'!C14,0),2)),0) -> 3 | H15: =ROUNDDOWN(SUM('WK1:WK5'!D14)/MAX(1,INDEX(FREQUENCY('WK1:WK5'!D14,0),2)),0) -> 6 | I15: =SUM(F15:H15) -> 12 | J15: =SUM('WK1:WK5'!O14) -> 0 | K15: =IF(AND((SUM([1]Summary!J15,J15)>0),[1]Summary!I15>0),(I15-(([1]Summary!I15-[1]Summary!J15)-(L15*([1]Summary!I15-[1]Summary!J15))))/(IF(SUM([1]Summary!J15,J15)>0,[1]Summary!J15+J15,0)),0%) -> 0 | L15: =IF(([1]Summary!I15)>0,(([1]Summary!I15-[1]Summary!J15)-(I15-J15))/(([1]Summary!I15-[1]Summary!J15)),100%) -> 0.14285714 | M15: =IF(I15=0,0%,IF((I15-[2]Sheet1!$G11+([2]Sheet1!$J11/12*1))=0, 0%,(I15-[2]Sheet1!$G11+([2]Sheet1!$J11/12*1))/([2]Sheet1!$G11+([2]Sheet1!$J11/12*1)))) -> 0.0098925362 | N15: =SUM('WK1:WK5'!M14) -> 10650 | O15: =(SUM('WK1:WK5'!M14)/MAX(1,INDEX(FREQUENCY('WK1:WK5'!M14,0),2)))/IF(F15+G15>0,F15+G15,"1") -> 443.75 | P15: =SUM(IF(SUM('WK1:WK5'!J14)>0,SUM('WK1:WK5'!T14)/((SUM('WK1:WK5'!J14)+SUM('WK1:WK5'!K14)+SUM('WK1:WK5'!P14))*0.3),0%),IF(SUM('WK1:WK5'!J14)>0,SUM('WK1:WK5'!U14)/((SUM('WK1:WK5'!J14)+SUM('WK1:WK5'!K14)+SUM('WK1:WK5'!P14))*0.1),0%),IF(SUM('WK1:WK5'!J14)>0,SUM('WK1:WK5'!V14)/((SUM('WK1:WK5'!J14)+SUM('WK1:WK5'!K14)+SUM('WK1:WK5'!P14))*0.3),0%)) -> 0 | Q15: =SUM('WK1:WK5'!Z14)/MAX(1,INDEX(FREQUENCY('WK1:WK5'!Z14,0),2)) -> 0 | R15: =IF(I15>0,SUM('WK1:WK5'!AE14)/MAX(1,INDEX(FREQUENCY('WK1:WK5'!AE14,0),2))/I15,0) -> 0 | S15: =RANK($J15,(J_Love,J_Maranatha,J_Goodnews,J_Heritage,J_Oyigbo,J_Revival)) -> 17 | T15: =RANK($K15,(K_Love,K_Maranatha,K_Goodnews,K_Heritage,K_Oyigbo,K_Revival)) -> 17 | U15: =RANK($L15,(L_Love,L_Maranatha,L_Goodnews,L_Heritage,L_Oyigbo,L_Revival),1) -> 25 | V15: =RANK($M15,(M_Love,M_Maranatha,M_Goodnews,M_Heritage,M_Oyigbo,M_Revival)) -> 10 | W15: =RANK($O15,(O_Love,O_Maranatha,O_Goodnews,O_Heritage,O_Oyigbo,O_Revival)) -> 11 | X15: =RANK($P15,(P_Love,P_Maranatha,P_Goodnews,P_Heritage,P_Oyigbo,P_Revival)) -> 1 | Y15: =RANK($Q15,(Q_Love,Q_Maranatha,Q_Goodnews,Q_Heritage,Q_Oyigbo,Q_Revival)) -> 1 | Z15: =RANK($R15,(R_Love,R_Maranatha,R_Goodnews,R_Heritage,R_Oyigbo,R_Revival)) -> 1 | AA15: =SUM(S15:Z15) -> 83 | AB15: =RANK(AA15,(AD_Love,AD_Maranatha,AD_Goodnews,AD_Heritage,AD_Oyigbo,AD_Revival),1) -> 19
B16: TOTAL | F16: =SUM(F12:F15) -> 127 | G16: =SUM(G12:G15) -> 150 | H16: =SUM(H12:H15) -> 153 | I16: =SUM(I12:I15) -> 430 | J16: =SUM(J12:J15) -> 2 | K16: =IF(SUM(K12:K15)>0,AVERAGEIF(K12:K15,"<>0"),0) -> 0.20238095 | L16: =IF(SUM(L12:L15)=0,100%,AVERAGEIF(L12:L15,"<>0")) -> -0.050017396 | M16: =IF(SUM(M12:M15)=0,0%,AVERAGEIF(M12:M15,"<>0")) -> 0.097983562 | N16: =SUM(N12:N15) -> 405530 | O16: =IF(SUM(O12:O15)>0,AVERAGEIF(O12:O15,"<>0"),0) -> 444.92326 | P16: =IF(SUM(P12:P15)>0,AVERAGEIF(P12:P15,"<>0"),0%) -> 0 | Q16: =IF(SUM(Q12:Q15)>0,AVERAGEIF(Q12:Q15,"<>0"),0) -> 0 | R16: =IF(SUM(R12:R15)>0,AVERAGEIF(R12:R15,"<>0"),0) -> 0 | S16: =RANK($J16,J_Zone) -> 6 | T16: =RANK($K16,K_Zone) -> 6 | U16: =RANK($L16,L_Zone) -> 3 | V16: =RANK($M16,M_Zone) -> 1 | W16: =RANK($O16,O_Zone) -> 3 | X16: =RANK($P16,P_Zone) -> 1 | Y16: =RANK($Q16,Q_Zone) -> 1 | Z16: =RANK($R16,R_Zone) -> 1 | AA16: =SUM(S16:Z16) -> 22 | AB16: =RANK(AA16,AD_Zone,1) -> 5
A17: Goodnews [Pst. OkeChukwu Ochulo] | B17: Rumukwurushi | C17: 8032724075 | D17: Pst. Frances Nabie | E17: Goodnews | F17: =ROUNDDOWN(SUM('WK1:WK5'!B16)/MAX(1,INDEX(FREQUENCY('WK1:WK5'!B16,0),2)),0) -> 52 | G17: =ROUNDDOWN(SUM('WK1:WK5'!C16)/MAX(1,INDEX(FREQUENCY('WK1:WK5'!C16,0),2)),0) -> 86 | H17: =ROUNDDOWN(SUM('WK1:WK5'!D16)/MAX(1,INDEX(FREQUENCY('WK1:WK5'!D16,0),2)),0) -> 77 | I17: =SUM(F17:H17) -> 215 | J17: =SUM('WK1:WK5'!O16) -> 1 | K17: =IF(AND((SUM([1]Summary!J17,J17)>0),[1]Summary!I17>0),(I17-(([1]Summary!I17-[1]Summary!J17)-(L17*([1]Summary!I17-[1]Summary!J17))))/(IF(SUM([1]Summary!J17,J17)>0,[1]Summary!J17+J17,0)),0%) -> 0.052631579 | L17: =IF(([1]Summary!I17)>0,(([1]Summary!I17-[1]Summary!J17)-(I17-J17))/(([1]Summary!I17-[1]Summary!J17)),100%) -> -0.4965035 | M17: =IF(I17=0,0%,IF((I17-[2]Sheet1!$G13+([2]Sheet1!$J13/12*1))=0, 0%,(I17-[2]Sheet1!$G13+([2]Sheet1!$J13/12*1))/([2]Sheet1!$G13+([2]Sheet1!$J13/12*1)))) -> 0.070693949 | N17: =SUM('WK1:WK5'!M16) -> 258640 | O17: =(SUM('WK1:WK5'!M16)/MAX(1,INDEX(FREQUENCY('WK1:WK5'!M16,0),2)))/IF(F17+G17>0,F17+G17,"1") -> 468.55072 | P17: =SUM(IF(SUM('WK1:WK5'!J16)>0,SUM('WK1:WK5'!T16)/((SUM('WK1:WK5'!J16)+SUM('WK1:WK5'!K16)+SUM('WK1:WK5'!P16))*0.3),0%),IF(SUM('WK1:WK5'!J16)>0,SUM('WK1:WK5'!U16)/((SUM('WK1:WK5'!J16)+SUM('WK1:WK5'!K16)+SUM('WK1:WK5'!P16))*0.1),0%),IF(SUM('WK1:WK5'!J16)>0,SUM('WK1:WK5'!V16)/((SUM('WK1:WK5'!J16)+SUM('WK1:WK5'!K16)+SUM('WK1:WK5'!P16))*0.3),0%)) -> 0 | Q17: =SUM('WK1:WK5'!Z16)/MAX(1,INDEX(FREQUENCY('WK1:WK5'!Z16,0),2)) -> 0 | R17: =IF(I17>0,SUM('WK1:WK5'!AE16)/MAX(1,INDEX(FREQUENCY('WK1:WK5'!AE16,0),2))/I17,0) -> 0 | S17: =RANK($J17,(J_Love,J_Maranatha,J_Goodnews,J_Heritage,J_Oyigbo,J_Revival)) -> 13 | T17: =RANK($K17,(K_Love,K_Maranatha,K_Goodnews,K_Heritage,K_Oyigbo,K_Revival)) -> 16 | U17: =RANK($L17,(L_Love,L_Maranatha,L_Goodnews,L_Heritage,L_Oyigbo,L_Revival),1) -> 4 | V17: =RANK($M17,(M_Love,M_Maranatha,M_Goodnews,M_Heritage,M_Oyigbo,M_Revival)) -> 7 | W17: =RANK($O17,(O_Love,O_Maranatha,O_Goodnews,O_Heritage,O_Oyigbo,O_Revival)) -> 9 | X17: =RANK($P17,(P_Love,P_Maranatha,P_Goodnews,P_Heritage,P_Oyigbo,P_Revival)) -> 1 | Y17: =RANK($Q17,(Q_Love,Q_Maranatha,Q_Goodnews,Q_Heritage,Q_Oyigbo,Q_Revival)) -> 1 | Z17: =RANK($R17,(R_Love,R_Maranatha,R_Goodnews,R_Heritage,R_Oyigbo,R_Revival)) -> 1 | AA17: =SUM(S17:Z17) -> 52 | AB17: =RANK(AA17,(AD_Love,AD_Maranatha,AD_Goodnews,AD_Heritage,AD_Oyigbo,AD_Revival),1) -> 4
B18: Igbo Etche | C18: 8029571213 | D18: Pst. Saviour Terkaa | E18: Shiloh | F18: =ROUNDDOWN(SUM('WK1:WK5'!B17)/MAX(1,INDEX(FREQUENCY('WK1:WK5'!B17,0),2)),0) -> 59 | G18: =ROUNDDOWN(SUM('WK1:WK5'!C17)/MAX(1,INDEX(FREQUENCY('WK1:WK5'!C17,0),2)),0) -> 82 | H18: =ROUNDDOWN(SUM('WK1:WK5'!D17)/MAX(1,INDEX(FREQUENCY('WK1:WK5'!D17,0),2)),0) -> 110 | I18: =SUM(F18:H18) -> 251 | J18: =SUM('WK1:WK5'!O17) -> 14 | K18: =IF(AND((SUM([1]Summary!J18,J18)>0),[1]Summary!I18>0),(I18-(([1]Summary!I18-[1]Summary!J18)-(L18*([1]Summary!I18-[1]Summary!J18))))/(IF(SUM([1]Summary!J18,J18)>0,[1]Summary!J18+J18,0)),0%) -> 1 | L18: =IF(([1]Summary!I18)>0,(([1]Summary!I18-[1]Summary!J18)-(I18-J18))/(([1]Summary!I18-[1]Summary!J18)),100%) -> -0.15609756 | M18: =IF(I18=0,0%,IF((I18-[2]Sheet1!$G14+([2]Sheet1!$J14/12*1))=0, 0%,(I18-[2]Sheet1!$G14+([2]Sheet1!$J14/12*1))/([2]Sheet1!$G14+([2]Sheet1!$J14/12*1)))) -> -0.14462635 | N18: =SUM('WK1:WK5'!M17) -> 198270 | O18: =(SUM('WK1:WK5'!M17)/MAX(1,INDEX(FREQUENCY('WK1:WK5'!M17,0),2)))/IF(F18+G18>0,F18+G18,"1") -> 351.54255 | P18: =SUM(IF(SUM('WK1:WK5'!J17)>0,SUM('WK1:WK5'!T17)/((SUM('WK1:WK5'!J17)+SUM('WK1:WK5'!K17)+SUM('WK1:WK5'!P17))*0.3),0%),IF(SUM('WK1:WK5'!J17)>0,SUM('WK1:WK5'!U17)/((SUM('WK1:WK5'!J17)+SUM('WK1:WK5'!K17)+SUM('WK1:WK5'!P17))*0.1),0%),IF(SUM('WK1:WK5'!J17)>0,SUM('WK1:WK5'!V17)/((SUM('WK1:WK5'!J17)+SUM('WK1:WK5'!K17)+SUM('WK1:WK5'!P17))*0.3),0%)) -> 0 | Q18: =SUM('WK1:WK5'!Z17)/MAX(1,INDEX(FREQUENCY('WK1:WK5'!Z17,0),2)) -> 0 | R18: =IF(I18>0,SUM('WK1:WK5'!AE17)/MAX(1,INDEX(FREQUENCY('WK1:WK5'!AE17,0),2))/I18,0) -> 0 | S18: =RANK($J18,(J_Love,J_Maranatha,J_Goodnews,J_Heritage,J_Oyigbo,J_Revival)) -> 1 | T18: =RANK($K18,(K_Love,K_Maranatha,K_Goodnews,K_Heritage,K_Oyigbo,K_Revival)) -> 1 | U18: =RANK($L18,(L_Love,L_Maranatha,L_Goodnews,L_Heritage,L_Oyigbo,L_Revival),1) -> 14 | V18: =RANK($M18,(M_Love,M_Maranatha,M_Goodnews,M_Heritage,M_Oyigbo,M_Revival)) -> 29 | W18: =RANK($O18,(O_Love,O_Maranatha,O_Goodnews,O_Heritage,O_Oyigbo,O_Revival)) -> 15 | X18: =RANK($P18,(P_Love,P_Maranatha,P_Goodnews,P_Heritage,P_Oyigbo,P_Revival)) -> 1 | Y18: =RANK($Q18,(Q_Love,Q_Maranatha,Q_Goodnews,Q_Heritage,Q_Oyigbo,Q_Revival)) -> 1 | Z18: =RANK($R18,(R_Love,R_Maranatha,R_Goodnews,R_Heritage,R_Oyigbo,R_Revival)) -> 1 | AA18: =SUM(S18:Z18) -> 63 | AB18: =RANK(AA18,(AD_Love,AD_Maranatha,AD_Goodnews,AD_Heritage,AD_Oyigbo,AD_Revival),1) -> 9
B19: Eneka | C19: 8168413880 | D19: Pst Okechukwu Ochulo | E19: Lords | F19: =ROUNDDOWN(SUM('WK1:WK5'!B18)/MAX(1,INDEX(FREQUENCY('WK1:WK5'!B18,0),2)),0) -> 9 | G19: =ROUNDDOWN(SUM('WK1:WK5'!C18)/MAX(1,INDEX(FREQUENCY('WK1:WK5'!C18,0),2)),0) -> 19 | H19: =ROUNDDOWN(SUM('WK1:WK5'!D18)/MAX(1,INDEX(FREQUENCY('WK1:WK5'!D18,0),2)),0) -> 19 | I19: =SUM(F19:H19) -> 47 | J19: =SUM('WK1:WK5'!O18) -> 0 | K19: =IF(AND((SUM([1]Summary!J19,J19)>0),[1]Summary!I19>0),(I19-(([1]Summary!I19-[1]Summary!J19)-(L19*([1]Summary!I19-[1]Summary!J19))))/(IF(SUM([1]Summary!J19,J19)>0,[1]Summary!J19+J19,0)),0%) -> 0 | L19: =IF(([1]Summary!I19)>0,(([1]Summary!I19-[1]Summary!J19)-(I19-J19))/(([1]Summary!I19-[1]Summary!J19)),100%) -> -0.02173913 | M19: =IF(I19=0,0%,IF((I19-[2]Sheet1!$G15+([2]Sheet1!$J15/12*1))=0, 0%,(I19-[2]Sheet1!$G15+([2]Sheet1!$J15/12*1))/([2]Sheet1!$G15+([2]Sheet1!$J15/12*1)))) -> -0.14835975 | N19: =SUM('WK1:WK5'!M18) -> 80400 | O19: =(SUM('WK1:WK5'!M18)/MAX(1,INDEX(FREQUENCY('WK1:WK5'!M18,0),2)))/IF(F19+G19>0,F19+G19,"1") -> 717.85714 | P19: =SUM(IF(SUM('WK1:WK5'!J18)>0,SUM('WK1:WK5'!T18)/((SUM('WK1:WK5'!J18)+SUM('WK1:WK5'!K18)+SUM('WK1:WK5'!P18))*0.3),0%),IF(SUM('WK1:WK5'!J18)>0,SUM('WK1:WK5'!U18)/((SUM('WK1:WK5'!J18)+SUM('WK1:WK5'!K18)+SUM('WK1:WK5'!P18))*0.1),0%),IF(SUM('WK1:WK5'!J18)>0,SUM('WK1:WK5'!V18)/((SUM('WK1:WK5'!J18)+SUM('WK1:WK5'!K18)+SUM('WK1:WK5'!P18))*0.3),0%)) -> 0 | Q19: =SUM('WK1:WK5'!Z18)/MAX(1,INDEX(FREQUENCY('WK1:WK5'!Z18,0),2)) -> 0 | R19: =IF(I19>0,SUM('WK1:WK5'!AE18)/MAX(1,INDEX(FREQUENCY('WK1:WK5'!AE18,0),2))/I19,0) -> 0 | S19: =RANK($J19,(J_Love,J_Maranatha,J_Goodnews,J_Heritage,J_Oyigbo,J_Revival)) -> 17 | T19: =RANK($K19,(K_Love,K_Maranatha,K_Goodnews,K_Heritage,K_Oyigbo,K_Revival)) -> 17 | U19: =RANK($L19,(L_Love,L_Maranatha,L_Goodnews,L_Heritage,L_Oyigbo,L_Revival),1) -> 20 | V19: =RANK($M19,(M_Love,M_Maranatha,M_Goodnews,M_Heritage,M_Oyigbo,M_Revival)) -> 30 | W19: =RANK($O19,(O_Love,O_Maranatha,O_Goodnews,O_Heritage,O_Oyigbo,O_Revival)) -> 3 | X19: =RANK($P19,(P_Love,P_Maranatha,P_Goodnews,P_Heritage,P_Oyigbo,P_Revival)) -> 1 | Y19: =RANK($Q19,(Q_Love,Q_Maranatha,Q_Goodnews,Q_Heritage,Q_Oyigbo,Q_Revival)) -> 1 | Z19: =RANK($R19,(R_Love,R_Maranatha,R_Goodnews,R_Heritage,R_Oyigbo,R_Revival)) -> 1 | AA19: =SUM(S19:Z19) -> 90 | AB19: =RANK(AA19,(AD_Love,AD_Maranatha,AD_Goodnews,AD_Heritage,AD_Oyigbo,AD_Revival),1) -> 21
B20: Elimgbu | C20: 8064324665 | D20: Pst. Joseph Onah | E20: Redemption | F20: =ROUNDDOWN(SUM('WK1:WK5'!B19)/MAX(1,INDEX(FREQUENCY('WK1:WK5'!B19,0),2)),0) -> 4 | G20: =ROUNDDOWN(SUM('WK1:WK5'!C19)/MAX(1,INDEX(FREQUENCY('WK1:WK5'!C19,0),2)),0) -> 2 | H20: =ROUNDDOWN(SUM('WK1:WK5'!D19)/MAX(1,INDEX(FREQUENCY('WK1:WK5'!D19,0),2)),0) -> 5 | I20: =SUM(F20:H20) -> 11 | J20: =SUM('WK1:WK5'!O19) -> 2 | K20: =IF(AND((SUM([1]Summary!J20,J20)>0),[1]Summary!I20>0),(I20-(([1]Summary!I20-[1]Summary!J20)-(L20*([1]Summary!I20-[1]Summary!J20))))/(IF(SUM([1]Summary!J20,J20)>0,[1]Summary!J20+J20,0)),0%) -> 0.4 | L20: =IF(([1]Summary!I20)>0,(([1]Summary!I20-[1]Summary!J20)-(I20-J20))/(([1]Summary!I20-[1]Summary!J20)),100%) -> 0.25 | M20: =IF(I20=0,0%,IF((I20-[2]Sheet1!$G16+([2]Sheet1!$J16/12*1))=0, 0%,(I20-[2]Sheet1!$G16+([2]Sheet1!$J16/12*1))/([2]Sheet1!$G16+([2]Sheet1!$J16/12*1)))) -> -0.12111618 | N20: =SUM('WK1:WK5'!M19) -> 40800 | O20: =(SUM('WK1:WK5'!M19)/MAX(1,INDEX(FREQUENCY('WK1:WK5'!M19,0),2)))/IF(F20+G20>0,F20+G20,"1") -> 1700 | P20: =SUM(IF(SUM('WK1:WK5'!J19)>0,SUM('WK1:WK5'!T19)/((SUM('WK1:WK5'!J19)+SUM('WK1:WK5'!K19)+SUM('WK1:WK5'!P19))*0.3),0%),IF(SUM('WK1:WK5'!J19)>0,SUM('WK1:WK5'!U19)/((SUM('WK1:WK5'!J19)+SUM('WK1:WK5'!K19)+SUM('WK1:WK5'!P19))*0.1),0%),IF(SUM('WK1:WK5'!J19)>0,SUM('WK1:WK5'!V19)/((SUM('WK1:WK5'!J19)+SUM('WK1:WK5'!K19)+SUM('WK1:WK5'!P19))*0.3),0%)) -> 0 | Q20: =SUM('WK1:WK5'!Z19)/MAX(1,INDEX(FREQUENCY('WK1:WK5'!Z19,0),2)) -> 0 | R20: =IF(I20>0,SUM('WK1:WK5'!AE19)/MAX(1,INDEX(FREQUENCY('WK1:WK5'!AE19,0),2))/I20,0) -> 0 | S20: =RANK($J20,(J_Love,J_Maranatha,J_Goodnews,J_Heritage,J_Oyigbo,J_Revival)) -> 9 | T20: =RANK($K20,(K_Love,K_Maranatha,K_Goodnews,K_Heritage,K_Oyigbo,K_Revival)) -> 8 | U20: =RANK($L20,(L_Love,L_Maranatha,L_Goodnews,L_Heritage,L_Oyigbo,L_Revival),1) -> 27 | V20: =RANK($M20,(M_Love,M_Maranatha,M_Goodnews,M_Heritage,M_Oyigbo,M_Revival)) -> 27 | W20: =RANK($O20,(O_Love,O_Maranatha,O_Goodnews,O_Heritage,O_Oyigbo,O_Revival)) -> 1 | X20: =RANK($P20,(P_Love,P_Maranatha,P_Goodnews,P_Heritage,P_Oyigbo,P_Revival)) -> 1 | Y20: =RANK($Q20,(Q_Love,Q_Maranatha,Q_Goodnews,Q_Heritage,Q_Oyigbo,Q_Revival)) -> 1 | Z20: =RANK($R20,(R_Love,R_Maranatha,R_Goodnews,R_Heritage,R_Oyigbo,R_Revival)) -> 1 | AA20: =SUM(S20:Z20) -> 75 | AB20: =RANK(AA20,(AD_Love,AD_Maranatha,AD_Goodnews,AD_Heritage,AD_Oyigbo,AD_Revival),1) -> 16
B21: Rumuodara | C21: 8174035100 | D21: Pst. Collins Obodo | E21: Upper room | F21: =ROUNDDOWN(SUM('WK1:WK5'!B20)/MAX(1,INDEX(FREQUENCY('WK1:WK5'!B20,0),2)),0) -> 13 | G21: =ROUNDDOWN(SUM('WK1:WK5'!C20)/MAX(1,INDEX(FREQUENCY('WK1:WK5'!C20,0),2)),0) -> 20 | H21: =ROUNDDOWN(SUM('WK1:WK5'!D20)/MAX(1,INDEX(FREQUENCY('WK1:WK5'!D20,0),2)),0) -> 27 | I21: =SUM(F21:H21) -> 60 | J21: =SUM('WK1:WK5'!O20) -> 2 | K21: =IF(AND((SUM([1]Summary!J21,J21)>0),[1]Summary!I21>0),(I21-(([1]Summary!I21-[1]Summary!J21)-(L21*([1]Summary!I21-[1]Summary!J21))))/(IF(SUM([1]Summary!J21,J21)>0,[1]Summary!J21+J21,0)),0%) -> 0.22222222 | L21: =IF(([1]Summary!I21)>0,(([1]Summary!I21-[1]Summary!J21)-(I21-J21))/(([1]Summary!I21-[1]Summary!J21)),100%) -> -0.56756757 | M21: =IF(I21=0,0%,IF((I21-[2]Sheet1!$G17+([2]Sheet1!$J17/12*1))=0, 0%,(I21-[2]Sheet1!$G17+([2]Sheet1!$J17/12*1))/([2]Sheet1!$G17+([2]Sheet1!$J17/12*1)))) -> -0.26430476 | N21: =SUM('WK1:WK5'!M20) -> 46560 | O21: =(SUM('WK1:WK5'!M20)/MAX(1,INDEX(FREQUENCY('WK1:WK5'!M20,0),2)))/IF(F21+G21>0,F21+G21,"1") -> 470.30303 | P21: =SUM(IF(SUM('WK1:WK5'!J20)>0,SUM('WK1:WK5'!T20)/((SUM('WK1:WK5'!J20)+SUM('WK1:WK5'!K20)+SUM('WK1:WK5'!P20))*0.3),0%),IF(SUM('WK1:WK5'!J20)>0,SUM('WK1:WK5'!U20)/((SUM('WK1:WK5'!J20)+SUM('WK1:WK5'!K20)+SUM('WK1:WK5'!P20))*0.1),0%),IF(SUM('WK1:WK5'!J20)>0,SUM('WK1:WK5'!V20)/((SUM('WK1:WK5'!J20)+SUM('WK1:WK5'!K20)+SUM('WK1:WK5'!P20))*0.3),0%)) -> 0 | Q21: =SUM('WK1:WK5'!Z20)/MAX(1,INDEX(FREQUENCY('WK1:WK5'!Z20,0),2)) -> 0 | R21: =IF(I21>0,SUM('WK1:WK5'!AE20)/MAX(1,INDEX(FREQUENCY('WK1:WK5'!AE20,0),2))/I21,0) -> 0 | S21: =RANK($J21,(J_Love,J_Maranatha,J_Goodnews,J_Heritage,J_Oyigbo,J_Revival)) -> 9 | T21: =RANK($K21,(K_Love,K_Maranatha,K_Goodnews,K_Heritage,K_Oyigbo,K_Revival)) -> 13 | U21: =RANK($L21,(L_Love,L_Maranatha,L_Goodnews,L_Heritage,L_Oyigbo,L_Revival),1) -> 2 | V21: =RANK($M21,(M_Love,M_Maranatha,M_Goodnews,M_Heritage,M_Oyigbo,M_Revival)) -> 36 | W21: =RANK($O21,(O_Love,O_Maranatha,O_Goodnews,O_Heritage,O_Oyigbo,O_Revival)) -> 8 | X21: =RANK($P21,(P_Love,P_Maranatha,P_Goodnews,P_Heritage,P_Oyigbo,P_Revival)) -> 1 | Y21: =RANK($Q21,(Q_Love,Q_Maranatha,Q_Goodnews,Q_Heritage,Q_Oyigbo,Q_Revival)) -> 1 | Z21: =RANK($R21,(R_Love,R_Maranatha,R_Goodnews,R_Heritage,R_Oyigbo,R_Revival)) -> 1 | AA21: =SUM(S21:Z21) -> 71 | AB21: =RANK(AA21,(AD_Love,AD_Maranatha,AD_Goodnews,AD_Heritage,AD_Oyigbo,AD_Revival),1) -> 12
B22: TOTAL | F22: =SUM(F17:F21) -> 137 | G22: =SUM(G17:G21) -> 209 | H22: =SUM(H17:H21) -> 238 | I22: =SUM(I17:I21) -> 584 | J22: =SUM(J17:J21) -> 19 | K22: =IF(SUM(K17:K21)>0,AVERAGEIF(K17:K21,"<>0"),0) -> 0.41871345 | L22: =IF(SUM(L17:L21)=0,100%,AVERAGEIF(L17:L21,"<>0")) -> -0.19838155 | M22: =IF(SUM(M17:M21)=0,0%,AVERAGEIF(M17:M21,"<>0")) -> -0.12154262 | N22: =SUM(N17:N21) -> 624670 | O22: =IF(SUM(O17:O21)>0,AVERAGEIF(O17:O21,"<>0"),0) -> 741.65069 | P22: =IF(SUM(P17:P21)>0,AVERAGEIF(P17:P21,"<>0"),0%) -> 0 | Q22: =IF(SUM(Q17:Q21)>0,AVERAGEIF(Q17:Q21,"<>0"),0) -> 0 | R22: =IF(SUM(R17:R21)>0,AVERAGEIF(R17:R21,"<>0"),0) -> 0 | S22: =RANK($J22,J_Zone) -> 2 | T22: =RANK($K22,K_Zone) -> 5 | U22: =RANK($L22,L_Zone) -> 5 | V22: =RANK($M22,M_Zone) -> 4 | W22: =RANK($O22,O_Zone) -> 1 | X22: =RANK($P22,P_Zone) -> 1 | Y22: =RANK($Q22,Q_Zone) -> 1 | Z22: =RANK($R22,R_Zone) -> 1 | AA22: =SUM(S22:Z22) -> 20 | AB22: =RANK(AA22,AD_Zone,1) -> 2
A23: Heritage [Pst. Moses Okwuonu] | B23: Eleme | C23: 7038053235 | D23: Pst. Moses Okwuonu | E23: Dominion | F23: =ROUNDDOWN(SUM('WK1:WK5'!B22)/MAX(1,INDEX(FREQUENCY('WK1:WK5'!B22,0),2)),0) -> 19 | G23: =ROUNDDOWN(SUM('WK1:WK5'!C22)/MAX(1,INDEX(FREQUENCY('WK1:WK5'!C22,0),2)),0) -> 37 | H23: =ROUNDDOWN(SUM('WK1:WK5'!D22)/MAX(1,INDEX(FREQUENCY('WK1:WK5'!D22,0),2)),0) -> 47 | I23: =SUM(F23:H23) -> 103 | J23: =SUM('WK1:WK5'!O22) -> 0 | K23: =IF(AND((SUM([1]Summary!J23,J23)>0),[1]Summary!I23>0),(I23-(([1]Summary!I23-[1]Summary!J23)-(L23*([1]Summary!I23-[1]Summary!J23))))/(IF(SUM([1]Summary!J23,J23)>0,[1]Summary!J23+J23,0)),0%) -> 0 | L23: =IF(([1]Summary!I23)>0,(([1]Summary!I23-[1]Summary!J23)-(I23-J23))/(([1]Summary!I23-[1]Summary!J23)),100%) -> -0.25609756 | M23: =IF(I23=0,0%,IF((I23-[2]Sheet1!$G19+([2]Sheet1!$J19/12*1))=0, 0%,(I23-[2]Sheet1!$G19+([2]Sheet1!$J19/12*1))/([2]Sheet1!$G19+([2]Sheet1!$J19/12*1)))) -> -0.20297655 | N23: =SUM('WK1:WK5'!M22) -> 122360 | O23: =(SUM('WK1:WK5'!M22)/MAX(1,INDEX(FREQUENCY('WK1:WK5'!M22,0),2)))/IF(F23+G23>0,F23+G23,"1") -> 546.25 | P23: =SUM(IF(SUM('WK1:WK5'!J22)>0,SUM('WK1:WK5'!T22)/((SUM('WK1:WK5'!J22)+SUM('WK1:WK5'!K22)+SUM('WK1:WK5'!P22))*0.3),0%),IF(SUM('WK1:WK5'!J22)>0,SUM('WK1:WK5'!U22)/((SUM('WK1:WK5'!J22)+SUM('WK1:WK5'!K22)+SUM('WK1:WK5'!P22))*0.1),0%),IF(SUM('WK1:WK5'!J22)>0,SUM('WK1:WK5'!V22)/((SUM('WK1:WK5'!J22)+SUM('WK1:WK5'!K22)+SUM('WK1:WK5'!P22))*0.3),0%)) -> 0 | Q23: =SUM('WK1:WK5'!Z22)/MAX(1,INDEX(FREQUENCY('WK1:WK5'!Z22,0),2)) -> 0 | R23: =IF(I23>0,SUM('WK1:WK5'!AE22)/MAX(1,INDEX(FREQUENCY('WK1:WK5'!AE22,0),2))/I23,0) -> 0 | S23: =RANK($J23,(J_Love,J_Maranatha,J_Goodnews,J_Heritage,J_Oyigbo,J_Revival)) -> 17 | T23: =RANK($K23,(K_Love,K_Maranatha,K_Goodnews,K_Heritage,K_Oyigbo,K_Revival)) -> 17 | U23: =RANK($L23,(L_Love,L_Maranatha,L_Goodnews,L_Heritage,L_Oyigbo,L_Revival),1) -> 8 | V23: =RANK($M23,(M_Love,M_Maranatha,M_Goodnews,M_Heritage,M_Oyigbo,M_Revival)) -> 32 | W23: =RANK($O23,(O_Love,O_Maranatha,O_Goodnews,O_Heritage,O_Oyigbo,O_Revival)) -> 5 | X23: =RANK($P23,(P_Love,P_Maranatha,P_Goodnews,P_Heritage,P_Oyigbo,P_Revival)) -> 1 | Y23: =RANK($Q23,(Q_Love,Q_Maranatha,Q_Goodnews,Q_Heritage,Q_Oyigbo,Q_Revival)) -> 1 | Z23: =RANK($R23,(R_Love,R_Maranatha,R_Goodnews,R_Heritage,R_Oyigbo,R_Revival)) -> 1 | AA23: =SUM(S23:Z23) -> 82 | AB23: =RANK(AA23,(AD_Love,AD_Maranatha,AD_Goodnews,AD_Heritage,AD_Oyigbo,AD_Revival),1) -> 18
B24: Onne | C24: 8066532318 | D24: Pst. Paul Kilsi | E24: Fruitful | F24: =ROUNDDOWN(SUM('WK1:WK5'!B23)/MAX(1,INDEX(FREQUENCY('WK1:WK5'!B23,0),2)),0) -> 0 | G24: =ROUNDDOWN(SUM('WK1:WK5'!C23)/MAX(1,INDEX(FREQUENCY('WK1:WK5'!C23,0),2)),0) -> 0 | H24: =ROUNDDOWN(SUM('WK1:WK5'!D23)/MAX(1,INDEX(FREQUENCY('WK1:WK5'!D23,0),2)),0) -> 0 | I24: =SUM(F24:H24) -> 0 | J24: =SUM('WK1:WK5'!O23) -> 0 | K24: =IF(AND((SUM([1]Summary!J24,J24)>0),[1]Summary!I24>0),(I24-(([1]Summary!I24-[1]Summary!J24)-(L24*([1]Summary!I24-[1]Summary!J24))))/(IF(SUM([1]Summary!J24,J24)>0,[1]Summary!J24+J24,0)),0%) -> 0 | L24: =IF(([1]Summary!I24)>0,(([1]Summary!I24-[1]Summary!J24)-(I24-J24))/(([1]Summary!I24-[1]Summary!J24)),100%) -> 1 | M24: =IF(I24=0,0%,IF((I24-[2]Sheet1!$G20+([2]Sheet1!$J20/12*1))=0, 0%,(I24-[2]Sheet1!$G20+([2]Sheet1!$J20/12*1))/([2]Sheet1!$G20+([2]Sheet1!$J20/12*1)))) -> 0 | N24: =SUM('WK1:WK5'!M23) -> 0 | O24: =(SUM('WK1:WK5'!M23)/MAX(1,INDEX(FREQUENCY('WK1:WK5'!M23,0),2)))/IF(F24+G24>0,F24+G24,"1") -> 0 | P24: =SUM(IF(SUM('WK1:WK5'!J23)>0,SUM('WK1:WK5'!T23)/((SUM('WK1:WK5'!J23)+SUM('WK1:WK5'!K23)+SUM('WK1:WK5'!P23))*0.3),0%),IF(SUM('WK1:WK5'!J23)>0,SUM('WK1:WK5'!U23)/((SUM('WK1:WK5'!J23)+SUM('WK1:WK5'!K23)+SUM('WK1:WK5'!P23))*0.1),0%),IF(SUM('WK1:WK5'!J23)>0,SUM('WK1:WK5'!V23)/((SUM('WK1:WK5'!J23)+SUM('WK1:WK5'!K23)+SUM('WK1:WK5'!P23))*0.3),0%)) -> 0 | Q24: =SUM('WK1:WK5'!Z23)/MAX(1,INDEX(FREQUENCY('WK1:WK5'!Z23,0),2)) -> 0 | R24: =IF(I24>0,SUM('WK1:WK5'!AE23)/MAX(1,INDEX(FREQUENCY('WK1:WK5'!AE23,0),2))/I24,0) -> 0 | S24: =RANK($J24,(J_Love,J_Maranatha,J_Goodnews,J_Heritage,J_Oyigbo,J_Revival)) -> 17 | T24: =RANK($K24,(K_Love,K_Maranatha,K_Goodnews,K_Heritage,K_Oyigbo,K_Revival)) -> 17 | U24: =RANK($L24,(L_Love,L_Maranatha,L_Goodnews,L_Heritage,L_Oyigbo,L_Revival),1) -> 29 | V24: =RANK($M24,(M_Love,M_Maranatha,M_Goodnews,M_Heritage,M_Oyigbo,M_Revival)) -> 11 | W24: =RANK($O24,(O_Love,O_Maranatha,O_Goodnews,O_Heritage,O_Oyigbo,O_Revival)) -> 29 | X24: =RANK($P24,(P_Love,P_Maranatha,P_Goodnews,P_Heritage,P_Oyigbo,P_Revival)) -> 1 | Y24: =RANK($Q24,(Q_Love,Q_Maranatha,Q_Goodnews,Q_Heritage,Q_Oyigbo,Q_Revival)) -> 1 | Z24: =RANK($R24,(R_Love,R_Maranatha,R_Goodnews,R_Heritage,R_Oyigbo,R_Revival)) -> 1 | AA24: =SUM(S24:Z24) -> 106 | AB24: =RANK(AA24,(AD_Love,AD_Maranatha,AD_Goodnews,AD_Heritage,AD_Oyigbo,AD_Revival),1) -> 25
B25: Elelenwo | C25: 8056448547 | D25: Pst. Raymond Atuh | E25: Heritage | F25: =ROUNDDOWN(SUM('WK1:WK5'!B24)/MAX(1,INDEX(FREQUENCY('WK1:WK5'!B24,0),2)),0) -> 42 | G25: =ROUNDDOWN(SUM('WK1:WK5'!C24)/MAX(1,INDEX(FREQUENCY('WK1:WK5'!C24,0),2)),0) -> 66 | H25: =ROUNDDOWN(SUM('WK1:WK5'!D24)/MAX(1,INDEX(FREQUENCY('WK1:WK5'!D24,0),2)),0) -> 61 | I25: =SUM(F25:H25) -> 169 | J25: =SUM('WK1:WK5'!O24) -> 2 | K25: =IF(AND((SUM([1]Summary!J25,J25)>0),[1]Summary!I25>0),(I25-(([1]Summary!I25-[1]Summary!J25)-(L25*([1]Summary!I25-[1]Summary!J25))))/(IF(SUM([1]Summary!J25,J25)>0,[1]Summary!J25+J25,0)),0%) -> 0.33333333 | L25: =IF(([1]Summary!I25)>0,(([1]Summary!I25-[1]Summary!J25)-(I25-J25))/(([1]Summary!I25-[1]Summary!J25)),100%) -> -0.19285714 | M25: =IF(I25=0,0%,IF((I25-[2]Sheet1!$G21+([2]Sheet1!$J21/12*1))=0, 0%,(I25-[2]Sheet1!$G21+([2]Sheet1!$J21/12*1))/([2]Sheet1!$G21+([2]Sheet1!$J21/12*1)))) -> -0.21353672 | N25: =SUM('WK1:WK5'!M24) -> 233155 | O25: =(SUM('WK1:WK5'!M24)/MAX(1,INDEX(FREQUENCY('WK1:WK5'!M24,0),2)))/IF(F25+G25>0,F25+G25,"1") -> 539.71065 | P25: =SUM(IF(SUM('WK1:WK5'!J24)>0,SUM('WK1:WK5'!T24)/((SUM('WK1:WK5'!J24)+SUM('WK1:WK5'!K24)+SUM('WK1:WK5'!P24))*0.3),0%),IF(SUM('WK1:WK5'!J24)>0,SUM('WK1:WK5'!U24)/((SUM('WK1:WK5'!J24)+SUM('WK1:WK5'!K24)+SUM('WK1:WK5'!P24))*0.1),0%),IF(SUM('WK1:WK5'!J24)>0,SUM('WK1:WK5'!V24)/((SUM('WK1:WK5'!J24)+SUM('WK1:WK5'!K24)+SUM('WK1:WK5'!P24))*0.3),0%)) -> 0 | Q25: =SUM('WK1:WK5'!Z24)/MAX(1,INDEX(FREQUENCY('WK1:WK5'!Z24,0),2)) -> 0 | R25: =IF(I25>0,SUM('WK1:WK5'!AE24)/MAX(1,INDEX(FREQUENCY('WK1:WK5'!AE24,0),2))/I25,0) -> 0 | S25: =RANK($J25,(J_Love,J_Maranatha,J_Goodnews,J_Heritage,J_Oyigbo,J_Revival)) -> 9 | T25: =RANK($K25,(K_Love,K_Maranatha,K_Goodnews,K_Heritage,K_Oyigbo,K_Revival)) -> 10 | U25: =RANK($L25,(L_Love,L_Maranatha,L_Goodnews,L_Heritage,L_Oyigbo,L_Revival),1) -> 11 | V25: =RANK($M25,(M_Love,M_Maranatha,M_Goodnews,M_Heritage,M_Oyigbo,M_Revival)) -> 34 | W25: =RANK($O25,(O_Love,O_Maranatha,O_Goodnews,O_Heritage,O_Oyigbo,O_Revival)) -> 6 | X25: =RANK($P25,(P_Love,P_Maranatha,P_Goodnews,P_Heritage,P_Oyigbo,P_Revival)) -> 1 | Y25: =RANK($Q25,(Q_Love,Q_Maranatha,Q_Goodnews,Q_Heritage,Q_Oyigbo,Q_Revival)) -> 1 | Z25: =RANK($R25,(R_Love,R_Maranatha,R_Goodnews,R_Heritage,R_Oyigbo,R_Revival)) -> 1 | AA25: =SUM(S25:Z25) -> 73 | AB25: =RANK(AA25,(AD_Love,AD_Maranatha,AD_Goodnews,AD_Heritage,AD_Oyigbo,AD_Revival),1) -> 14
B26: Eleme | C26: 9057050605 | D26: Pst. Alex Eneremadu | E26: Convenant House | F26: =ROUNDDOWN(SUM('WK1:WK5'!B25)/MAX(1,INDEX(FREQUENCY('WK1:WK5'!B25,0),2)),0) -> 9 | G26: =ROUNDDOWN(SUM('WK1:WK5'!C25)/MAX(1,INDEX(FREQUENCY('WK1:WK5'!C25,0),2)),0) -> 8 | H26: =ROUNDDOWN(SUM('WK1:WK5'!D25)/MAX(1,INDEX(FREQUENCY('WK1:WK5'!D25,0),2)),0) -> 10 | I26: =SUM(F26:H26) -> 27 | J26: =SUM('WK1:WK5'!O25) -> 3 | K26: =IF(AND((SUM([1]Summary!J26,J26)>0),[1]Summary!I26>0),(I26-(([1]Summary!I26-[1]Summary!J26)-(L26*([1]Summary!I26-[1]Summary!J26))))/(IF(SUM([1]Summary!J26,J26)>0,[1]Summary!J26+J26,0)),0%) -> 0.6 | L26: =IF(([1]Summary!I26)>0,(([1]Summary!I26-[1]Summary!J26)-(I26-J26))/(([1]Summary!I26-[1]Summary!J26)),100%) -> -0.26315789 | M26: =IF(I26=0,0%,IF((I26-[2]Sheet1!$G22+([2]Sheet1!$J22/12*1))=0, 0%,(I26-[2]Sheet1!$G22+([2]Sheet1!$J22/12*1))/([2]Sheet1!$G22+([2]Sheet1!$J22/12*1)))) -> -0.015821699 | N26: =SUM('WK1:WK5'!M25) -> 38940 | O26: =(SUM('WK1:WK5'!M25)/MAX(1,INDEX(FREQUENCY('WK1:WK5'!M25,0),2)))/IF(F26+G26>0,F26+G26,"1") -> 572.64706 | P26: =SUM(IF(SUM('WK1:WK5'!J25)>0,SUM('WK1:WK5'!T25)/((SUM('WK1:WK5'!J25)+SUM('WK1:WK5'!K25)+SUM('WK1:WK5'!P25))*0.3),0%),IF(SUM('WK1:WK5'!J25)>0,SUM('WK1:WK5'!U25)/((SUM('WK1:WK5'!J25)+SUM('WK1:WK5'!K25)+SUM('WK1:WK5'!P25))*0.1),0%),IF(SUM('WK1:WK5'!J25)>0,SUM('WK1:WK5'!V25)/((SUM('WK1:WK5'!J25)+SUM('WK1:WK5'!K25)+SUM('WK1:WK5'!P25))*0.3),0%)) -> 0 | Q26: =SUM('WK1:WK5'!Z25)/MAX(1,INDEX(FREQUENCY('WK1:WK5'!Z25,0),2)) -> 0 | R26: =IF(I26>0,SUM('WK1:WK5'!AE25)/MAX(1,INDEX(FREQUENCY('WK1:WK5'!AE25,0),2))/I26,0) -> 0 | S26: =RANK($J26,(J_Love,J_Maranatha,J_Goodnews,J_Heritage,J_Oyigbo,J_Revival)) -> 8 | T26: =RANK($K26,(K_Love,K_Maranatha,K_Goodnews,K_Heritage,K_Oyigbo,K_Revival)) -> 7 | U26: =RANK($L26,(L_Love,L_Maranatha,L_Goodnews,L_Heritage,L_Oyigbo,L_Revival),1) -> 7 | V26: =RANK($M26,(M_Love,M_Maranatha,M_Goodnews,M_Heritage,M_Oyigbo,M_Revival)) -> 22 | W26: =RANK($O26,(O_Love,O_Maranatha,O_Goodnews,O_Heritage,O_Oyigbo,O_Revival)) -> 4 | X26: =RANK($P26,(P_Love,P_Maranatha,P_Goodnews,P_Heritage,P_Oyigbo,P_Revival)) -> 1 | Y26: =RANK($Q26,(Q_Love,Q_Maranatha,Q_Goodnews,Q_Heritage,Q_Oyigbo,Q_Revival)) -> 1 | Z26: =RANK($R26,(R_Love,R_Maranatha,R_Goodnews,R_Heritage,R_Oyigbo,R_Revival)) -> 1 | AA26: =SUM(S26:Z26) -> 51 | AB26: =RANK(AA26,(AD_Love,AD_Maranatha,AD_Goodnews,AD_Heritage,AD_Oyigbo,AD_Revival),1) -> 3
B27: TOTAL | F27: =SUM(F23:F26) -> 70 | G27: =SUM(G23:G26) -> 111 | H27: =SUM(H23:H26) -> 118 | I27: =SUM(I23:I26) -> 299 | J27: =SUM(J23:J26) -> 5 | K27: =IF(SUM(K23:K26)>0,AVERAGEIF(K23:K26,"<>0"),0) -> 0.46666667 | L27: =IF(SUM(L23:L26)=0,100%,AVERAGEIF(L23:L26,"<>0")) -> 0.07197185 | M27: =IF(SUM(M23:M26)=0,0%,AVERAGEIF(M23:M26,"<>0")) -> -0.14411165 | N27: =SUM(N23:N26) -> 394455 | O27: =IF(SUM(O23:O26)>0,AVERAGEIF(O23:O26,"<>0"),0) -> 552.86924 | P27: =IF(SUM(P23:P26)>0,AVERAGEIF(P23:P26,"<>0"),0%) -> 0 | Q27: =IF(SUM(Q23:Q26)>0,AVERAGEIF(Q23:Q26,"<>0"),0) -> 0 | R27: =IF(SUM(R23:R26)>0,AVERAGEIF(R23:R26,"<>0"),0) -> 0 | S27: =RANK($J27,J_Zone) -> 4 | T27: =RANK($K27,K_Zone) -> 4 | U27: =RANK($L27,L_Zone) -> 2 | V27: =RANK($M27,M_Zone) -> 6 | W27: =RANK($O27,O_Zone) -> 2 | X27: =RANK($P27,P_Zone) -> 1 | Y27: =RANK($Q27,Q_Zone) -> 1 | Z27: =RANK($R27,R_Zone) -> 1 | AA27: =SUM(S27:Z27) -> 21 | AB27: =RANK(AA27,AD_Zone,1) -> 3
A28: Oyigbo [Pst. Vincent Otebele] | B28: Umuebelu IV | C28: 8037239097 | D28: Pst. Patrick Anaelechi | E28: I - care | F28: =ROUNDDOWN(SUM('WK1:WK5'!B27)/MAX(1,INDEX(FREQUENCY('WK1:WK5'!B27,0),2)),0) -> 29 | G28: =ROUNDDOWN(SUM('WK1:WK5'!C27)/MAX(1,INDEX(FREQUENCY('WK1:WK5'!C27,0),2)),0) -> 30 | H28: =ROUNDDOWN(SUM('WK1:WK5'!D27)/MAX(1,INDEX(FREQUENCY('WK1:WK5'!D27,0),2)),0) -> 44 | I28: =SUM(F28:H28) -> 103 | J28: =SUM('WK1:WK5'!O27) -> 12 | K28: =IF(AND((SUM([1]Summary!J28,J28)>0),[1]Summary!I28>0),(I28-(([1]Summary!I28-[1]Summary!J28)-(L28*([1]Summary!I28-[1]Summary!J28))))/(IF(SUM([1]Summary!J28,J28)>0,[1]Summary!J28+J28,0)),0%) -> 0.85714286 | L28: =IF(([1]Summary!I28)>0,(([1]Summary!I28-[1]Summary!J28)-(I28-J28))/(([1]Summary!I28-[1]Summary!J28)),100%) -> -0.083333333 | M28: =IF(I28=0,0%,IF((I28-[2]Sheet1!$G24+([2]Sheet1!$J24/12*1))=0, 0%,(I28-[2]Sheet1!$G24+([2]Sheet1!$J24/12*1))/([2]Sheet1!$G24+([2]Sheet1!$J24/12*1)))) -> 0.16415407 | N28: =SUM('WK1:WK5'!M27) -> 68540 | O28: =(SUM('WK1:WK5'!M27)/MAX(1,INDEX(FREQUENCY('WK1:WK5'!M27,0),2)))/IF(F28+G28>0,F28+G28,"1") -> 290.42373 | P28: =SUM(IF(SUM('WK1:WK5'!J27)>0,SUM('WK1:WK5'!T27)/((SUM('WK1:WK5'!J27)+SUM('WK1:WK5'!K27)+SUM('WK1:WK5'!P27))*0.3),0%),IF(SUM('WK1:WK5'!J27)>0,SUM('WK1:WK5'!U27)/((SUM('WK1:WK5'!J27)+SUM('WK1:WK5'!K27)+SUM('WK1:WK5'!P27))*0.1),0%),IF(SUM('WK1:WK5'!J27)>0,SUM('WK1:WK5'!V27)/((SUM('WK1:WK5'!J27)+SUM('WK1:WK5'!K27)+SUM('WK1:WK5'!P27))*0.3),0%)) -> 0 | Q28: =SUM('WK1:WK5'!Z27)/MAX(1,INDEX(FREQUENCY('WK1:WK5'!Z27,0),2)) -> 0 | R28: =IF(I28>0,SUM('WK1:WK5'!AE27)/MAX(1,INDEX(FREQUENCY('WK1:WK5'!AE27,0),2))/I28,0) -> 0 | S28: =RANK($J28,(J_Love,J_Maranatha,J_Goodnews,J_Heritage,J_Oyigbo,J_Revival)) -> 2 | T28: =RANK($K28,(K_Love,K_Maranatha,K_Goodnews,K_Heritage,K_Oyigbo,K_Revival)) -> 4 | U28: =RANK($L28,(L_Love,L_Maranatha,L_Goodnews,L_Heritage,L_Oyigbo,L_Revival),1) -> 17 | V28: =RANK($M28,(M_Love,M_Maranatha,M_Goodnews,M_Heritage,M_Oyigbo,M_Revival)) -> 4 | W28: =RANK($O28,(O_Love,O_Maranatha,O_Goodnews,O_Heritage,O_Oyigbo,O_Revival)) -> 19 | X28: =RANK($P28,(P_Love,P_Maranatha,P_Goodnews,P_Heritage,P_Oyigbo,P_Revival)) -> 1 | Y28: =RANK($Q28,(Q_Love,Q_Maranatha,Q_Goodnews,Q_Heritage,Q_Oyigbo,Q_Revival)) -> 1 | Z28: =RANK($R28,(R_Love,R_Maranatha,R_Goodnews,R_Heritage,R_Oyigbo,R_Revival)) -> 1 | AA28: =SUM(S28:Z28) -> 49 | AB28: =RANK(AA28,(AD_Love,AD_Maranatha,AD_Goodnews,AD_Heritage,AD_Oyigbo,AD_Revival),1) -> 2
B29: Imo River | C29: 8037081352 | D29: Pst. Chimezie Lewechi | E29: Favour | F29: =ROUNDDOWN(SUM('WK1:WK5'!B28)/MAX(1,INDEX(FREQUENCY('WK1:WK5'!B28,0),2)),0) -> 3 | G29: =ROUNDDOWN(SUM('WK1:WK5'!C28)/MAX(1,INDEX(FREQUENCY('WK1:WK5'!C28,0),2)),0) -> 13 | H29: =ROUNDDOWN(SUM('WK1:WK5'!D28)/MAX(1,INDEX(FREQUENCY('WK1:WK5'!D28,0),2)),0) -> 18 | I29: =SUM(F29:H29) -> 34 | J29: =SUM('WK1:WK5'!O28) -> 0 | K29: =IF(AND((SUM([1]Summary!J29,J29)>0),[1]Summary!I29>0),(I29-(([1]Summary!I29-[1]Summary!J29)-(L29*([1]Summary!I29-[1]Summary!J29))))/(IF(SUM([1]Summary!J29,J29)>0,[1]Summary!J29+J29,0)),0%) -> 0 | L29: =IF(([1]Summary!I29)>0,(([1]Summary!I29-[1]Summary!J29)-(I29-J29))/(([1]Summary!I29-[1]Summary!J29)),100%) -> -0.13333333 | M29: =IF(I29=0,0%,IF((I29-[2]Sheet1!$G25+([2]Sheet1!$J25/12*1))=0, 0%,(I29-[2]Sheet1!$G25+([2]Sheet1!$J25/12*1))/([2]Sheet1!$G25+([2]Sheet1!$J25/12*1)))) -> -0.34998492 | N29: =SUM('WK1:WK5'!M28) -> 16330 | O29: =(SUM('WK1:WK5'!M28)/MAX(1,INDEX(FREQUENCY('WK1:WK5'!M28,0),2)))/IF(F29+G29>0,F29+G29,"1") -> 255.15625 | P29: =SUM(IF(SUM('WK1:WK5'!J28)>0,SUM('WK1:WK5'!T28)/((SUM('WK1:WK5'!J28)+SUM('WK1:WK5'!K28)+SUM('WK1:WK5'!P28))*0.3),0%),IF(SUM('WK1:WK5'!J28)>0,SUM('WK1:WK5'!U28)/((SUM('WK1:WK5'!J28)+SUM('WK1:WK5'!K28)+SUM('WK1:WK5'!P28))*0.1),0%),IF(SUM('WK1:WK5'!J28)>0,SUM('WK1:WK5'!V28)/((SUM('WK1:WK5'!J28)+SUM('WK1:WK5'!K28)+SUM('WK1:WK5'!P28))*0.3),0%)) -> 0 | Q29: =SUM('WK1:WK5'!Z28)/MAX(1,INDEX(FREQUENCY('WK1:WK5'!Z28,0),2)) -> 0 | R29: =IF(I29>0,SUM('WK1:WK5'!AE28)/MAX(1,INDEX(FREQUENCY('WK1:WK5'!AE28,0),2))/I29,0) -> 0 | S29: =RANK($J29,(J_Love,J_Maranatha,J_Goodnews,J_Heritage,J_Oyigbo,J_Revival)) -> 17 | T29: =RANK($K29,(K_Love,K_Maranatha,K_Goodnews,K_Heritage,K_Oyigbo,K_Revival)) -> 17 | U29: =RANK($L29,(L_Love,L_Maranatha,L_Goodnews,L_Heritage,L_Oyigbo,L_Revival),1) -> 16 | V29: =RANK($M29,(M_Love,M_Maranatha,M_Goodnews,M_Heritage,M_Oyigbo,M_Revival)) -> 37 | W29: =RANK($O29,(O_Love,O_Maranatha,O_Goodnews,O_Heritage,O_Oyigbo,O_Revival)) -> 23 | X29: =RANK($P29,(P_Love,P_Maranatha,P_Goodnews,P_Heritage,P_Oyigbo,P_Revival)) -> 1 | Y29: =RANK($Q29,(Q_Love,Q_Maranatha,Q_Goodnews,Q_Heritage,Q_Oyigbo,Q_Revival)) -> 1 | Z29: =RANK($R29,(R_Love,R_Maranatha,R_Goodnews,R_Heritage,R_Oyigbo,R_Revival)) -> 1 | AA29: =SUM(S29:Z29) -> 113 | AB29: =RANK(AA29,(AD_Love,AD_Maranatha,AD_Goodnews,AD_Heritage,AD_Oyigbo,AD_Revival),1) -> 38
B30: Location Rd Oyigbo | C30: 8033011811 | D30: Pst. Vincent Otebele | E30: Praise | F30: =ROUNDDOWN(SUM('WK1:WK5'!B29)/MAX(1,INDEX(FREQUENCY('WK1:WK5'!B29,0),2)),0) -> 30 | G30: =ROUNDDOWN(SUM('WK1:WK5'!C29)/MAX(1,INDEX(FREQUENCY('WK1:WK5'!C29,0),2)),0) -> 45 | H30: =ROUNDDOWN(SUM('WK1:WK5'!D29)/MAX(1,INDEX(FREQUENCY('WK1:WK5'!D29,0),2)),0) -> 41 | I30: =SUM(F30:H30) -> 116 | J30: =SUM('WK1:WK5'!O29) -> 10 | K30: =IF(AND((SUM([1]Summary!J30,J30)>0),[1]Summary!I30>0),(I30-(([1]Summary!I30-[1]Summary!J30)-(L30*([1]Summary!I30-[1]Summary!J30))))/(IF(SUM([1]Summary!J30,J30)>0,[1]Summary!J30+J30,0)),0%) -> 0.71428571 | L30: =IF(([1]Summary!I30)>0,(([1]Summary!I30-[1]Summary!J30)-(I30-J30))/(([1]Summary!I30-[1]Summary!J30)),100%) -> 0.0093457944 | M30: =IF(I30=0,0%,IF((I30-[2]Sheet1!$G26+([2]Sheet1!$J26/12*1))=0, 0%,(I30-[2]Sheet1!$G26+([2]Sheet1!$J26/12*1))/([2]Sheet1!$G26+([2]Sheet1!$J26/12*1)))) -> -0.082174147 | N30: =SUM('WK1:WK5'!M29) -> 75770 | O30: =(SUM('WK1:WK5'!M29)/MAX(1,INDEX(FREQUENCY('WK1:WK5'!M29,0),2)))/IF(F30+G30>0,F30+G30,"1") -> 252.56667 | P30: =SUM(IF(SUM('WK1:WK5'!J29)>0,SUM('WK1:WK5'!T29)/((SUM('WK1:WK5'!J29)+SUM('WK1:WK5'!K29)+SUM('WK1:WK5'!P29))*0.3),0%),IF(SUM('WK1:WK5'!J29)>0,SUM('WK1:WK5'!U29)/((SUM('WK1:WK5'!J29)+SUM('WK1:WK5'!K29)+SUM('WK1:WK5'!P29))*0.1),0%),IF(SUM('WK1:WK5'!J29)>0,SUM('WK1:WK5'!V29)/((SUM('WK1:WK5'!J29)+SUM('WK1:WK5'!K29)+SUM('WK1:WK5'!P29))*0.3),0%)) -> 0 | Q30: =SUM('WK1:WK5'!Z29)/MAX(1,INDEX(FREQUENCY('WK1:WK5'!Z29,0),2)) -> 0 | R30: =IF(I30>0,SUM('WK1:WK5'!AE29)/MAX(1,INDEX(FREQUENCY('WK1:WK5'!AE29,0),2))/I30,0) -> 0 | S30: =RANK($J30,(J_Love,J_Maranatha,J_Goodnews,J_Heritage,J_Oyigbo,J_Revival)) -> 3 | T30: =RANK($K30,(K_Love,K_Maranatha,K_Goodnews,K_Heritage,K_Oyigbo,K_Revival)) -> 6 | U30: =RANK($L30,(L_Love,L_Maranatha,L_Goodnews,L_Heritage,L_Oyigbo,L_Revival),1) -> 21 | V30: =RANK($M30,(M_Love,M_Maranatha,M_Goodnews,M_Heritage,M_Oyigbo,M_Revival)) -> 24 | W30: =RANK($O30,(O_Love,O_Maranatha,O_Goodnews,O_Heritage,O_Oyigbo,O_Revival)) -> 24 | X30: =RANK($P30,(P_Love,P_Maranatha,P_Goodnews,P_Heritage,P_Oyigbo,P_Revival)) -> 1 | Y30: =RANK($Q30,(Q_Love,Q_Maranatha,Q_Goodnews,Q_Heritage,Q_Oyigbo,Q_Revival)) -> 1 | Z30: =RANK($R30,(R_Love,R_Maranatha,R_Goodnews,R_Heritage,R_Oyigbo,R_Revival)) -> 1 | AA30: =SUM(S30:Z30) -> 81 | AB30: =RANK(AA30,(AD_Love,AD_Maranatha,AD_Goodnews,AD_Heritage,AD_Oyigbo,AD_Revival),1) -> 17
B31: Pipe Line Oyigbo | C31: 8036666983 | D31: Pst. Gregory Omonribhor | E31: Restoration | F31: =ROUNDDOWN(SUM('WK1:WK5'!B30)/MAX(1,INDEX(FREQUENCY('WK1:WK5'!B30,0),2)),0) -> 13 | G31: =ROUNDDOWN(SUM('WK1:WK5'!C30)/MAX(1,INDEX(FREQUENCY('WK1:WK5'!C30,0),2)),0) -> 29 | H31: =ROUNDDOWN(SUM('WK1:WK5'!D30)/MAX(1,INDEX(FREQUENCY('WK1:WK5'!D30,0),2)),0) -> 48 | I31: =SUM(F31:H31) -> 90 | J31: =SUM('WK1:WK5'!O30) -> 0 | K31: =IF(AND((SUM([1]Summary!J31,J31)>0),[1]Summary!I31>0),(I31-(([1]Summary!I31-[1]Summary!J31)-(L31*([1]Summary!I31-[1]Summary!J31))))/(IF(SUM([1]Summary!J31,J31)>0,[1]Summary!J31+J31,0)),0%) -> 0 | L31: =IF(([1]Summary!I31)>0,(([1]Summary!I31-[1]Summary!J31)-(I31-J31))/(([1]Summary!I31-[1]Summary!J31)),100%) -> -0.23287671 | M31: =IF(I31=0,0%,IF((I31-[2]Sheet1!$G27+([2]Sheet1!$J27/12*1))=0, 0%,(I31-[2]Sheet1!$G27+([2]Sheet1!$J27/12*1))/([2]Sheet1!$G27+([2]Sheet1!$J27/12*1)))) -> -0.091899569 | N31: =SUM('WK1:WK5'!M30) -> 18690 | O31: =(SUM('WK1:WK5'!M30)/MAX(1,INDEX(FREQUENCY('WK1:WK5'!M30,0),2)))/IF(F31+G31>0,F31+G31,"1") -> 222.5 | P31: =SUM(IF(SUM('WK1:WK5'!J30)>0,SUM('WK1:WK5'!T30)/((SUM('WK1:WK5'!J30)+SUM('WK1:WK5'!K30)+SUM('WK1:WK5'!P30))*0.3),0%),IF(SUM('WK1:WK5'!J30)>0,SUM('WK1:WK5'!U30)/((SUM('WK1:WK5'!J30)+SUM('WK1:WK5'!K30)+SUM('WK1:WK5'!P30))*0.1),0%),IF(SUM('WK1:WK5'!J30)>0,SUM('WK1:WK5'!V30)/((SUM('WK1:WK5'!J30)+SUM('WK1:WK5'!K30)+SUM('WK1:WK5'!P30))*0.3),0%)) -> 0 | Q31: =SUM('WK1:WK5'!Z30)/MAX(1,INDEX(FREQUENCY('WK1:WK5'!Z30,0),2)) -> 0 | R31: =IF(I31>0,SUM('WK1:WK5'!AE30)/MAX(1,INDEX(FREQUENCY('WK1:WK5'!AE30,0),2))/I31,0) -> 0 | S31: =RANK($J31,(J_Love,J_Maranatha,J_Goodnews,J_Heritage,J_Oyigbo,J_Revival)) -> 17 | T31: =RANK($K31,(K_Love,K_Maranatha,K_Goodnews,K_Heritage,K_Oyigbo,K_Revival)) -> 17 | U31: =RANK($L31,(L_Love,L_Maranatha,L_Goodnews,L_Heritage,L_Oyigbo,L_Revival),1) -> 10 | V31: =RANK($M31,(M_Love,M_Maranatha,M_Goodnews,M_Heritage,M_Oyigbo,M_Revival)) -> 25 | W31: =RANK($O31,(O_Love,O_Maranatha,O_Goodnews,O_Heritage,O_Oyigbo,O_Revival)) -> 26 | X31: =RANK($P31,(P_Love,P_Maranatha,P_Goodnews,P_Heritage,P_Oyigbo,P_Revival)) -> 1 | Y31: =RANK($Q31,(Q_Love,Q_Maranatha,Q_Goodnews,Q_Heritage,Q_Oyigbo,Q_Revival)) -> 1 | Z31: =RANK($R31,(R_Love,R_Maranatha,R_Goodnews,R_Heritage,R_Oyigbo,R_Revival)) -> 1 | AA31: =SUM(S31:Z31) -> 98 | AB31: =RANK(AA31,(AD_Love,AD_Maranatha,AD_Goodnews,AD_Heritage,AD_Oyigbo,AD_Revival),1) -> 23
B32: Kom-kom Oyigbo | C32: 8065956392 | D32: Pst. Peter Omoko | E32: Royal Tabernacle | F32: =ROUNDDOWN(SUM('WK1:WK5'!B31)/MAX(1,INDEX(FREQUENCY('WK1:WK5'!B31,0),2)),0) -> 7 | G32: =ROUNDDOWN(SUM('WK1:WK5'!C31)/MAX(1,INDEX(FREQUENCY('WK1:WK5'!C31,0),2)),0) -> 12 | H32: =ROUNDDOWN(SUM('WK1:WK5'!D31)/MAX(1,INDEX(FREQUENCY('WK1:WK5'!D31,0),2)),0) -> 23 | I32: =SUM(F32:H32) -> 42 | J32: =SUM('WK1:WK5'!O31) -> 2 | K32: =IF(AND((SUM([1]Summary!J32,J32)>0),[1]Summary!I32>0),(I32-(([1]Summary!I32-[1]Summary!J32)-(L32*([1]Summary!I32-[1]Summary!J32))))/(IF(SUM([1]Summary!J32,J32)>0,[1]Summary!J32+J32,0)),0%) -> 0.28571429 | L32: =IF(([1]Summary!I32)>0,(([1]Summary!I32-[1]Summary!J32)-(I32-J32))/(([1]Summary!I32-[1]Summary!J32)),100%) -> -0.052631579 | M32: =IF(I32=0,0%,IF((I32-[2]Sheet1!$G28+([2]Sheet1!$J28/12*1))=0, 0%,(I32-[2]Sheet1!$G28+([2]Sheet1!$J28/12*1))/([2]Sheet1!$G28+([2]Sheet1!$J28/12*1)))) -> -0.51271655 | N32: =SUM('WK1:WK5'!M31) -> 13550 | O32: =(SUM('WK1:WK5'!M31)/MAX(1,INDEX(FREQUENCY('WK1:WK5'!M31,0),2)))/IF(F32+G32>0,F32+G32,"1") -> 178.28947 | P32: =SUM(IF(SUM('WK1:WK5'!J31)>0,SUM('WK1:WK5'!T31)/((SUM('WK1:WK5'!J31)+SUM('WK1:WK5'!K31)+SUM('WK1:WK5'!P31))*0.3),0%),IF(SUM('WK1:WK5'!J31)>0,SUM('WK1:WK5'!U31)/((SUM('WK1:WK5'!J31)+SUM('WK1:WK5'!K31)+SUM('WK1:WK5'!P31))*0.1),0%),IF(SUM('WK1:WK5'!J31)>0,SUM('WK1:WK5'!V31)/((SUM('WK1:WK5'!J31)+SUM('WK1:WK5'!K31)+SUM('WK1:WK5'!P31))*0.3),0%)) -> 0 | Q32: =SUM('WK1:WK5'!Z31)/MAX(1,INDEX(FREQUENCY('WK1:WK5'!Z31,0),2)) -> 0 | R32: =IF(I32>0,SUM('WK1:WK5'!AE31)/MAX(1,INDEX(FREQUENCY('WK1:WK5'!AE31,0),2))/I32,0) -> 0 | S32: =RANK($J32,(J_Love,J_Maranatha,J_Goodnews,J_Heritage,J_Oyigbo,J_Revival)) -> 9 | T32: =RANK($K32,(K_Love,K_Maranatha,K_Goodnews,K_Heritage,K_Oyigbo,K_Revival)) -> 12 | U32: =RANK($L32,(L_Love,L_Maranatha,L_Goodnews,L_Heritage,L_Oyigbo,L_Revival),1) -> 18 | V32: =RANK($M32,(M_Love,M_Maranatha,M_Goodnews,M_Heritage,M_Oyigbo,M_Revival)) -> 39 | W32: =RANK($O32,(O_Love,O_Maranatha,O_Goodnews,O_Heritage,O_Oyigbo,O_Revival)) -> 28 | X32: =RANK($P32,(P_Love,P_Maranatha,P_Goodnews,P_Heritage,P_Oyigbo,P_Revival)) -> 1 | Y32: =RANK($Q32,(Q_Love,Q_Maranatha,Q_Goodnews,Q_Heritage,Q_Oyigbo,Q_Revival)) -> 1 | Z32: =RANK($R32,(R_Love,R_Maranatha,R_Goodnews,R_Heritage,R_Oyigbo,R_Revival)) -> 1 | AA32: =SUM(S32:Z32) -> 109 | AB32: =RANK(AA32,(AD_Love,AD_Maranatha,AD_Goodnews,AD_Heritage,AD_Oyigbo,AD_Revival),1) -> 37
